Workbook

Sheet DASHBOARD
A1: UK PENSION SALARY SACRIFICE MODEL · EXECUTIVE DASHBOARD
A2: Example Co Ltd | Tax Year 2024/25 | 25 Employees | Salary Sacrifice: Active | Data as at 09 May 2026
B4: EMPLOYEE OUTCOMES
B5: Total Take-Home (Post) £ | F5: Avg Take-Home Change £ | J5: Total EE Pension £ | N5: Avg EE Tax Saving £ | R5: Avg EE NI Saving £ | V5: Participation Rate
B6: =CALC_ENGINE!R29 | F6: =CALC_ENGINE!AJ29/25 | J6: =CALC_ENGINE!AB29 | N6: =(CALC_ENGINE!O29-CALC_ENGINE!Z29)/25 | R6: =(CALC_ENGINE!P29-CALC_ENGINE!AA29)/25 | V6: =COUNTIF(CALC_ENGINE!K4:K28,"Yes")/25
B7: Annual, all staff | F7: Per employee p.a. | J7: Salary sacrificed | N7: PAYE reduction | R7: NI reduction | V7: On salary sacrifice
B9: EMPLOYER OUTCOMES
B10: Total ER Cost (Post) £ | F10: ER Cost Change £ | J10: Gross ER NI Saving £ | N10: NI Saving per EE £ | R10: Total ER Pension £ | V10: Total Pension to Scheme £
B11: =CALC_ENGINE!AI29 | F11: =CALC_ENGINE!AI29-CALC_ENGINE!U29 | J11: =CALC_ENGINE!AF29 | N11: =CALC_ENGINE!AF29/25 | R11: =CALC_ENGINE!AD29 | V11: =CALC_ENGINE!AB29+CALC_ENGINE!AD29
B12: Salary+NI+Pension | F12: vs pre-sacrifice | J12: Annual saving | N12: Average per employee | R12: Employer contributions | V12: Combined EE+ER
B14: Department | C14: ER NI Saving £ | D14: EE Take-Home Chg £ | E14: Total Pension £
B15: Finance | C15: =DEPT_SUMMARY!I4 | D15: =DEPT_SUMMARY!J4 | E15: =DEPT_SUMMARY!H4
B16: HR | C16: =DEPT_SUMMARY!I5 | D16: =DEPT_SUMMARY!J5 | E16: =DEPT_SUMMARY!H5
B17: Operations | C17: =DEPT_SUMMARY!I6 | D17: =DEPT_SUMMARY!J6 | E17: =DEPT_SUMMARY!H6
B18: Sales | C18: =DEPT_SUMMARY!I7 | D18: =DEPT_SUMMARY!J7 | E18: =DEPT_SUMMARY!H7
B19: Tech | C19: =DEPT_SUMMARY!I8 | D19: =DEPT_SUMMARY!J8 | E19: =DEPT_SUMMARY!H8
B22: Metric | C22: Pre-Sacrifice £ | D22: Post-Sacrifice £
B23: PAYE Tax | C23: =CALC_ENGINE!O29 | D23: =CALC_ENGINE!Z29
B24: Employee NI | C24: =CALC_ENGINE!P29 | D24: =CALC_ENGINE!AA29
B25: EE Pension | C25: =CALC_ENGINE!Q29 | D25: =CALC_ENGINE!AB29
B26: ER Pension | C26: =CALC_ENGINE!S29 | D26: =CALC_ENGINE!AD29
B27: ER NI | C27: =CALC_ENGINE!T29 | D27: =CALC_ENGINE!AE29
B30: Component | C30: Amount £
B31: EE Pension | C31: =CALC_ENGINE!AB29
B32: ER Pension | C32: =CALC_ENGINE!AD29
B33: NI Shared to EEs | C33: =CALC_ENGINE!AG29
B35: Employee | C35: Take-Home Change £
B36: =EMPLOYEE_IMPACT!B4 | C36: =EMPLOYEE_IMPACT!I4
B37: =EMPLOYEE_IMPACT!B5 | C37: =EMPLOYEE_IMPACT!I5
B38: =EMPLOYEE_IMPACT!B6 | C38: =EMPLOYEE_IMPACT!I6
B39: =EMPLOYEE_IMPACT!B7 | C39: =EMPLOYEE_IMPACT!I7
B40: =EMPLOYEE_IMPACT!B8 | C40: =EMPLOYEE_IMPACT!I8
B41: =EMPLOYEE_IMPACT!B9 | C41: =EMPLOYEE_IMPACT!I9
B42: =EMPLOYEE_IMPACT!B10 | C42: =EMPLOYEE_IMPACT!I10
B43: =EMPLOYEE_IMPACT!B11 | C43: =EMPLOYEE_IMPACT!I11
B44: =EMPLOYEE_IMPACT!B12 | C44: =EMPLOYEE_IMPACT!I12
B45: KEY INSIGHTS | Salary sacrifice reduces the employee's gross for PAYE and NI, creating tax efficiency for both parties. The employer saves ER NI at 13.8% on all sacrificed amounts — this saving can be retained, shared or reinvested. Higher-rate taxpayers see the greatest take-home improvement per £ sacrificed. Ensure no employee's post-sacrifice salary falls below National Minimum Wage. Verify Annual Allowance for high earners (see AUDIT_CHECKS tab).
B46: =EMPLOYEE_IMPACT!B14 | C46: =EMPLOYEE_IMPACT!I14
B47: =EMPLOYEE_IMPACT!B15 | C47: =EMPLOYEE_IMPACT!I15
B48: =EMPLOYEE_IMPACT!B16 | C48: =EMPLOYEE_IMPACT!I16
...

Sheet ASSUMPTIONS
A1: UK PENSION SALARY SACRIFICE MODEL — ASSUMPTIONS & INPUTS
A2: All yellow cells are inputs. Blue cells are calculated. Do not edit grey/white formula cells.
B4: A. TAX YEAR & GENERAL SETTINGS
B5: Tax Year | C5: 2024/25
B6: Payroll Frequency | C6: Monthly
B7: Number of Pay Periods p.a. | C7: 12
B8: Company Name | C8: Example Co Ltd
B9: Model Version | C9: v1.0
B10: Model Date | C10: 09/05/2026
B12: B. INCOME TAX BANDS (England, Wales & NI)
B13: Band | C13: Lower Limit £ | D13: Upper Limit £ | E13: Rate %
B14: Personal Allowance | C14: 0 | D14: 12570 | E14: 0
B15: Basic Rate | C15: 12570 | D15: 50270 | E15: 0.2
B16: Higher Rate | C16: 50270 | D16: 125140 | E16: 0.4
B17: Additional Rate | C17: 125140 | D17: Unlimited | E17: 0.45
B18: PA Taper (£2 per £1 over £100k) | C18: 100000 | D18: 125140 | E18: Tapered
B21: C. EMPLOYEE NATIONAL INSURANCE
B22: Band | C22: Weekly Lower £ | D22: Weekly Upper £ | E22: Rate %
B23: Below LEL | C23: 0 | D23: 123 | E23: 0
B24: LEL to PT | C24: 123 | D24: 242 | E24: 0
B25: PT to UEL | C25: 242 | D25: 967 | E25: 0.08
B26: Above UEL | C26: 967 | D26: No limit | E26: 0.02
B29: D. EMPLOYER NATIONAL INSURANCE
B30: Band | C30: Weekly Lower £ | D30: Weekly Upper £ | E30: Rate %
B31: Below ST | C31: 0 | D31: 175 | E31: 0
B32: At or above ST | C32: 175 | D32: No limit | E32: 0.138
B33: Employment Allowance (£) | C33: 5000
B34: Employment Allowance Eligible? | C34: Yes
B37: E. PENSION CONTRIBUTION BASIS
B38: Qualifying Earnings Lower Limit £ p.a. | C38: 6240
B39: Qualifying Earnings Upper Limit £ p.a. | C39: 50270
B40: Annual Allowance £ | C40: 60000
B41: Money Purchase Annual Allowance £ | C41: 10000
B42: Lifetime Allowance | C42: Abolished Apr 2024
B45: F. DEFAULT CONTRIBUTION RATES
B46: Default Employee Contribution Rate | C46: 0.05
B47: Default Employer Contribution Rate | C47: 0.03
B48: Pension Calculation Basis | C48: Qualifying Earnings
B49: (Options: Qualifying Earnings / Full Salary / Full incl. Bonus)
B52: G. EMPLOYER NI SAVING DISPOSITION
...

Sheet EMPLOYEE_DATA
A1: EMPLOYEE DATA — Input Sheet | Yellow = editable inputs | Blue = auto-calculated
A2: Emp ID | B2: First Name | C2: Last Name | D2: Department | E2: Job Title | F2: Employment Type | G2: Start Date | H2: Annual Basic Salary £ | I2: Annual Bonus £ | J2: Total Annual Earnings £ | K2: EE Contrib Rate % | L2: ER Contrib Rate % | M2: Override Rates? Y/N | N2: Sacrifice On? Y/N | O2: Pension Basis Override | P2: NI Category | Q2: Scottish Taxpayer? Y/N | R2: Notes
A3: E001 | B3: Alice | C3: Hartley | D3: Finance | E3: CFO | F3: Full-time | G3: 01/04/2020 | H3: 180000 | I3: 20000 | J3: =H3+I3 | K3: 0.05 | L3: 0.03 | M3: N | N3: Y | P3: A | Q3: N
A4: E002 | B4: James | C4: Patel | D4: Finance | E4: Finance Director | F4: Full-time | G4: 15/06/2018 | H4: 120000 | I4: 15000 | J4: =H4+I4 | K4: 0.05 | L4: 0.03 | M4: N | N4: Y | P4: A | Q4: N
A5: E003 | B5: Priya | C5: Sharma | D5: Finance | E5: Senior Accountant | F5: Full-time | G5: 01/09/2021 | H5: 62000 | I5: 5000 | J5: =H5+I5 | K5: 0.05 | L5: 0.03 | M5: N | N5: Y | P5: A | Q5: N
A6: E004 | B6: Tom | C6: Williams | D6: Finance | E6: Accountant | F6: Full-time | G6: 01/03/2023 | H6: 42000 | I6: 2000 | J6: =H6+I6 | K6: 0.05 | L6: 0.03 | M6: N | N6: Y | P6: A | Q6: N
A7: E005 | B7: Emma | C7: Clarke | D7: Finance | E7: Finance Assistant | F7: Full-time | G7: 01/07/2024 | H7: 28000 | I7: 0 | J7: =H7+I7 | K7: 0.05 | L7: 0.03 | M7: N | N7: Y | P7: A | Q7: N
A8: E006 | B8: David | C8: Johnson | D8: HR | E8: HR Director | F8: Full-time | G8: 01/01/2019 | H8: 95000 | I8: 10000 | J8: =H8+I8 | K8: 0.05 | L8: 0.03 | M8: N | N8: Y | P8: A | Q8: N
A9: E007 | B9: Sarah | C9: Thompson | D9: HR | E9: HR Manager | F9: Full-time | G9: 01/04/2020 | H9: 58000 | I9: 4000 | J9: =H9+I9 | K9: 0.05 | L9: 0.03 | M9: N | N9: Y | P9: A | Q9: N
A10: E008 | B10: Luke | C10: Evans | D10: HR | E10: HR Advisor | F10: Full-time | G10: 01/08/2022 | H10: 38000 | I10: 1500 | J10: =H10+I10 | K10: 0.05 | L10: 0.03 | M10: N | N10: Y | P10: A | Q10: N
A11: E009 | B11: Nina | C11: Roberts | D11: HR | E11: HR Administrator | F11: Part-time | G11: 01/11/2023 | H11: 22000 | I11: 0 | J11: =H11+I11 | K11: 0.05 | L11: 0.03 | M11: N | N11: Y | P11: A | Q11: N
A12: E010 | B12: Ben | C12: Morris | D12: Operations | E12: Operations Director | F12: Full-time | G12: 01/06/2017 | H12: 110000 | I12: 12000 | J12: =H12+I12 | K12: 0.05 | L12: 0.03 | M12: N | N12: Y | P12: A | Q12: N
A13: E011 | B13: Kate | C13: Wilson | D13: Operations | E13: Operations Manager | F13: Full-time | G13: 01/02/2019 | H13: 72000 | I13: 6000 | J13: =H13+I13 | K13: 0.05 | L13: 0.03 | M13: N | N13: Y | P13: A | Q13: N
A14: E012 | B14: Sam | C14: Brown | D14: Operations | E14: Senior Analyst | F14: Full-time | G14: 01/05/2021 | H14: 54000 | I14: 3500 | J14: =H14+I14 | K14: 0.05 | L14: 0.03 | M14: N | N14: Y | P14: A | Q14: N
... A27: E025 | B27: Ella | C27: King | D27: Tech | E27: Junior Developer | F27: Full-time | G27: 01/01/2025 | H27: 35000 | I27: 0 | J27: =H27+I27 | K27: 0.05 | L27: 0.03 | M27: N | N27: Y | P27: A | Q27: N
A28: TOTALS | H28: =SUM(H3:H27) | I28: =SUM(I3:I27) | J28: =SUM(J3:J27)

Sheet TAX_NI_TABLES
A1: TAX & NI LOOKUP TABLES — Referenced by Calculation Engine
B3: ANNUAL NI THRESHOLDS (Weekly × 52)
B4: Threshold | C4: Weekly £ | D4: Annual £
B5: Lower Earnings Limit (LEL) | C5: 123 | D5: =C5*52
B6: Primary Threshold (PT) | C6: 242 | D6: =C6*52
B7: Upper Earnings Limit (UEL) | C7: 967 | D7: =C7*52
B8: Secondary Threshold (ST) | C8: 175 | D8: =C8*52
B11: INCOME TAX QUICK REFERENCE
B12: Description | C12: Value | D12: Source
B13: Personal Allowance | C13: 12570 | D13: ASSUMPTIONS!C15
B14: Basic Rate (20%) | C14: 0.2 | D14: ASSUMPTIONS!E15
B15: Higher Rate (40%) | C15: 0.4 | D15: ASSUMPTIONS!E16
B16: Additional Rate (45%) | C16: 0.45 | D16: ASSUMPTIONS!E17
B17: HR Threshold (annual) | C17: 50270 | D17: ASSUMPTIONS!C16
B18: AR Threshold (annual) | C18: 125140 | D18: ASSUMPTIONS!C17
B19: PA Taper Start | C19: 100000 | D19: ASSUMPTIONS!C18
B22: NI RATES QUICK REFERENCE
B23: Description | C23: Rate | D23: Source
B24: EE NI: PT to UEL | C24: 0.08
B25: EE NI: Above UEL | C25: 0.02
B26: ER NI: At/above ST | C26: 0.138
B27: PT Annual | C27: 12570
B28: UEL Annual | C28: 50270
B29: ST Annual | C29: 9100

Sheet CALC_ENGINE
A1: SALARY SACRIFICE CALCULATION ENGINE | All formulas link to ASSUMPTIONS & EMPLOYEE_DATA | Do not edit formula cells
A2: EMPLOYEE | D2: EARNINGS | G2: PENSION SETUP | L2: PRE-SACRIFICE BASELINE | V2: POST-SACRIFICE | AJ2: IMPACT ANALYSIS | AS2: CHECKS
A3: Emp ID | B3: Name | C3: Department | D3: Basic Salary £ | E3: Bonus £ | F3: Total Earnings £ | G3: Pension Basis | H3: Pensionable Pay £ | I3: EE Rate % | J3: ER Rate % | K3: Sacrifice On? | L3: Gross Pay £ | M3: Eff. PA £ | N3: Taxable Inc £ | O3: PAYE Tax £ | P3: EE NI £ | Q3: EE Pension £ (Net Pay/RAS) | R3: Take-Home £ (Pre) | S3: ER Pension £ | T3: ER NI £ | U3: Total ER Cost £ | V3: Sacrificed £ | W3: Post-Sac Gross £ | X3: Eff. PA (Post) £ | Y3: Taxable Inc (Post) £ | Z3: PAYE Tax (Post) £ | AA3: EE NI (Post) £ | AB3: EE Pension £ (SS) | AC3: Take-Home £ (Post) | AD3: ER Pension £ (Post) | AE3: ER NI (Post) £ | AF3: ER NI Saving £ | AG3: NI Share→EE £ | AH3: NI Retain/ Reinvest £ | AI3: Total ER Cost (Post) £ | AJ3: Take-Home Change £ | AK3: Take-Home Change % | AL3: EE Pension Change £ | AM3: ER Cost Change £ | AN3: ER NI Saving £ | AO3: Total Pension (EE+ER) £ | AP3: Ann Allowance Remaining £ | AQ3: Tax Band (Pre) | AR3: Tax Band (Post) | AS3: Flags
A4: =EMPLOYEE_DATA!A3 | B4: =EMPLOYEE_DATA!B3&" "&EMPLOYEE_DATA!C3 | C4: =EMPLOYEE_DATA!D3 | D4: =EMPLOYEE_DATA!H3 | E4: =EMPLOYEE_DATA!I3 | F4: =EMPLOYEE_DATA!J3 | G4: =IF(EMPLOYEE_DATA!O3<>"",EMPLOYEE_DATA!O3,ASSUMPTIONS!$C$48) | H4: =IF(G4="Qualifying Earnings",MAX(0,MIN(F4,ASSUMPTIONS!$C$39)-ASSUMPTIONS!$C$38),IF(G4="Full Salary",D4,F4)) | I4: =IF(EMPLOYEE_DATA!M3="Y",EMPLOYEE_DATA!K3,ASSUMPTIONS!$C$46) | J4: =IF(EMPLOYEE_DATA!M3="Y",EMPLOYEE_DATA!L3,ASSUMPTIONS!$C$47) | K4: =IF(AND(EMPLOYEE_DATA!N3="Y",ASSUMPTIONS!$C$62="On"),"Yes","No") | L4: =F4 | M4: =MAX(0,IF(L4<=ASSUMPTIONS!$C$18,ASSUMPTIONS!$C$15,ASSUMPTIONS!$C$15-INT((L4-ASSUMPTIONS!$C$18)/2))) | N4: =MAX(0,L4-M4) | O4: =MAX(0,MIN(N4,MAX(0,ASSUMPTIONS!$C$16-M4))*ASSUMPTIONS!$E$15+MAX(0,MIN(N4,ASSUMPTIONS!$C$17-M4)-MAX(0,ASSUMPTIONS!$C$16-M4))*ASSUMPTIONS!$E$16+MAX(0,N4-MAX(0,ASSUMPTIONS!$C$17-M4))*ASSUMPTIONS!$E$17) | P4: =MAX(0,MIN(L4,TAX_NI_TABLES!$D$7)-TAX_NI_TABLES!$D$6)*ASSUMPTIONS!$E$25+MAX(0,L4-TAX_NI_TABLES!$D$7)*ASSUMPTIONS!$E$26 | Q4: =H4*I4 | R4: =L4-O4-P4-Q4 | S4: =H4*J4 | T4: =MAX(0,L4-TAX_NI_TABLES!$D$8)*ASSUMPTIONS!$E$32 | U4: =L4+S4+T4 | V4: =IF(K4="Yes",H4*I4,0) | W4: =L4-V4 | X4: =MAX(0,IF(W4<=ASSUMPTIONS!$C$18,ASSUMPTIONS!$C$15,ASSUMPTIONS!$C$15-INT((W4-ASSUMPTIONS!$C$18)/2))) | Y4: =MAX(0,W4-X4) | Z4: =MAX(0,MIN(Y4,MAX(0,ASSUMPTIONS!$C$16-X4))*ASSUMPTIONS!$E$15+MAX(0,MIN(Y4,ASSUMPTIONS!$C$17-X4)-MAX(0,ASSUMPTIONS!$C$16-X4))*ASSUMPTIONS!$E$16+MAX(0,Y4-MAX(0,ASSUMPTIONS!$C$17-X4))*ASSUMPTIONS!$E$17) | AA4: =MAX(0,MIN(W4,TAX_NI_TABLES!$D$7)-TAX_NI_TABLES!$D$6)*ASSUMPTIONS!$E$25+MAX(0,W4-TAX_NI_TABLES!$D$7)*ASSUMPTIONS!$E$26 | AB4: =V4 | AC4: =W4-Z4-AA4+AG4 | AD4: =H4*J4+IF(ASSUMPTIONS!$C$53="Reinvest in Pension",AF4*ASSUMPTIONS!$C$55,0) | AE4: =MAX(0,W4-TAX_NI_TABLES!$D$8)*ASSUMPTIONS!$E$32 | AF4: =MAX(0,T4-AE4) | AG4: =IF(ASSUMPTIONS!$C$53="Share with Employees",AF4*ASSUMPTIONS!$C$55,0) | AH4: =AF4-AG4 | AI4: =W4+AD4+AE4+AG4 | AJ4: =AC4-R4 | AK4: =IF(R4<>0,(AC4-R4)/R4,0) | AL4: =AB4-Q4 | AM4: =AI4-U4 | AN4: =AH4 | AO4: =AB4+AD4 | AP4: =ASSUMPTIONS!$C$40-AO4 | AQ4: =IF(F4<=ASSUMPTIONS!$C$15,"Personal Allowance",IF(F4<=ASSUMPTIONS!$C$16,"Basic Rate",IF(F4<=ASSUMPTIONS!$C$17,"Higher Rate","Additional Rate"))) | AR4: =IF(W4<=ASSUMPTIONS!$C$15,"Personal Allowance",IF(W4<=ASSUMPTIONS!$C$16,"Basic Rate",IF(W4<=ASSUMPTIONS!$C$17,"Higher Rate","Additional Rate"))) | AS4: =IF(AP4<0,"⚠ AA Breach!","")&IF(V4>F4,"⚠ Sacrifice>Salary","")&IF(AC4<0,"⚠ Neg Take-Home","")
A5: =EMPLOYEE_DATA!A4 | B5: =EMPLOYEE_DATA!B4&" "&EMPLOYEE_DATA!C4 | C5: =EMPLOYEE_DATA!D4 | D5: =EMPLOYEE_DATA!H4 | E5: =EMPLOYEE_DATA!I4 | F5: =EMPLOYEE_DATA!J4 | G5: =IF(EMPLOYEE_DATA!O4<>"",EMPLOYEE_DATA!O4,ASSUMPTIONS!$C$48) | H5: =IF(G5="Qualifying Earnings",MAX(0,MIN(F5,ASSUMPTIONS!$C$39)-ASSUMPTIONS!$C$38),IF(G5="Full Salary",D5,F5)) | I5: =IF(EMPLOYEE_DATA!M4="Y",EMPLOYEE_DATA!K4,ASSUMPTIONS!$C$46) | J5: =IF(EMPLOYEE_DATA!M4="Y",EMPLOYEE_DATA!L4,ASSUMPTIONS!$C$47) | K5: =IF(AND(EMPLOYEE_DATA!N4="Y",ASSUMPTIONS!$C$62="On"),"Yes","No") | L5: =F5 | M5: =MAX(0,IF(L5<=ASSUMPTIONS!$C$18,ASSUMPTIONS!$C$15,ASSUMPTIONS!$C$15-INT((L5-ASSUMPTIONS!$C$18)/2))) | N5: =MAX(0,L5-M5) | O5: =MAX(0,MIN(N5,MAX(0,ASSUMPTIONS!$C$16-M5))*ASSUMPTIONS!$E$15+MAX(0,MIN(N5,ASSUMPTIONS!$C$17-M5)-MAX(0,ASSUMPTIONS!$C$16-M5))*ASSUMPTIONS!$E$16+MAX(0,N5-MAX(0,ASSUMPTIONS!$C$17-M5))*ASSUMPTIONS!$E$17) | P5: =MAX(0,MIN(L5,TAX_NI_TABLES!$D$7)-TAX_NI_TABLES!$D$6)*ASSUMPTIONS!$E$25+MAX(0,L5-TAX_NI_TABLES!$D$7)*ASSUMPTIONS!$E$26 | Q5: =H5*I5 | R5: =L5-O5-P5-Q5 | S5: =H5*J5 | T5: =MAX(0,L5-TAX_NI_TABLES!$D$8)*ASSUMPTIONS!$E$32 | U5: =L5+S5+T5 | V5: =IF(K5="Yes",H5*I5,0) | W5: =L5-V5 | X5: =MAX(0,IF(W5<=ASSUMPTIONS!$C$18,ASSUMPTIONS!$C$15,ASSUMPTIONS!$C$15-INT((W5-ASSUMPTIONS!$C$18)/2))) | Y5: =MAX(0,W5-X5) | Z5: =MAX(0,MIN(Y5,MAX(0,ASSUMPTIONS!$C$16-X5))*ASSUMPTIONS!$E$15+MAX(0,MIN(Y5,ASSUMPTIONS!$C$17-X5)-MAX(0,ASSUMPTIONS!$C$16-X5))*ASSUMPTIONS!$E$16+MAX(0,Y5-MAX(0,ASSUMPTIONS!$C$17-X5))*ASSUMPTIONS!$E$17) | AA5: =MAX(0,MIN(W5,TAX_NI_TABLES!$D$7)-TAX_NI_TABLES!$D$6)*ASSUMPTIONS!$E$25+MAX(0,W5-TAX_NI_TABLES!$D$7)*ASSUMPTIONS!$E$26 | AB5: =V5 | AC5: =W5-Z5-AA5+AG5 | AD5: =H5*J5+IF(ASSUMPTIONS!$C$53="Reinvest in Pension",AF5*ASSUMPTIONS!$C$55,0) | AE5: =MAX(0,W5-TAX_NI_TABLES!$D$8)*ASSUMPTIONS!$E$32 | AF5: =MAX(0,T5-AE5) | AG5: =IF(ASSUMPTIONS!$C$53="Share with Employees",AF5*ASSUMPTIONS!$C$55,0) | AH5: =AF5-AG5 | AI5: =W5+AD5+AE5+AG5 | AJ5: =AC5-R5 | AK5: =IF(R5<>0,(AC5-R5)/R5,0) | AL5: =AB5-Q5 | AM5: =AI5-U5 | AN5: =AH5 | AO5: =AB5+AD5 | AP5: =ASSUMPTIONS!$C$40-AO5 | AQ5: =IF(F5<=ASSUMPTIONS!$C$15,"Personal Allowance",IF(F5<=ASSUMPTIONS!$C$16,"Basic Rate",IF(F5<=ASSUMPTIONS!$C$17,"Higher Rate","Additional Rate"))) | AR5: =IF(W5<=ASSUMPTIONS!$C$15,"Personal Allowance",IF(W5<=ASSUMPTIONS!$C$16,"Basic Rate",IF(W5<=ASSUMPTIONS!$C$17,"Higher Rate","Additional Rate"))) | AS5: =IF(AP5<0,"⚠ AA Breach!","")&IF(V5>F5,"⚠ Sacrifice>Salary","")&IF(AC5<0,"⚠ Neg Take-Home","")
A6: =EMPLOYEE_DATA!A5 | B6: =EMPLOYEE_DATA!B5&" "&EMPLOYEE_DATA!C5 | C6: =EMPLOYEE_DATA!D5 | D6: =EMPLOYEE_DATA!H5 | E6: =EMPLOYEE_DATA!I5 | F6: =EMPLOYEE_DATA!J5 | G6: =IF(EMPLOYEE_DATA!O5<>"",EMPLOYEE_DATA!O5,ASSUMPTIONS!$C$48) | H6: =IF(G6="Qualifying Earnings",MAX(0,MIN(F6,ASSUMPTIONS!$C$39)-ASSUMPTIONS!$C$38),IF(G6="Full Salary",D6,F6)) | I6: =IF(EMPLOYEE_DATA!M5="Y",EMPLOYEE_DATA!K5,ASSUMPTIONS!$C$46) | J6: =IF(EMPLOYEE_DATA!M5="Y",EMPLOYEE_DATA!L5,ASSUMPTIONS!$C$47) | K6: =IF(AND(EMPLOYEE_DATA!N5="Y",ASSUMPTIONS!$C$62="On"),"Yes","No") | L6: =F6 | M6: =MAX(0,IF(L6<=ASSUMPTIONS!$C$18,ASSUMPTIONS!$C$15,ASSUMPTIONS!$C$15-INT((L6-ASSUMPTIONS!$C$18)/2))) | N6: =MAX(0,L6-M6) | O6: =MAX(0,MIN(N6,MAX(0,ASSUMPTIONS!$C$16-M6))*ASSUMPTIONS!$E$15+MAX(0,MIN(N6,ASSUMPTIONS!$C$17-M6)-MAX(0,ASSUMPTIONS!$C$16-M6))*ASSUMPTIONS!$E$16+MAX(0,N6-MAX(0,ASSUMPTIONS!$C$17-M6))*ASSUMPTIONS!$E$17) | P6: =MAX(0,MIN(L6,TAX_NI_TABLES!$D$7)-TAX_NI_TABLES!$D$6)*ASSUMPTIONS!$E$25+MAX(0,L6-TAX_NI_TABLES!$D$7)*ASSUMPTIONS!$E$26 | Q6: =H6*I6 | R6: =L6-O6-P6-Q6 | S6: =H6*J6 | T6: =MAX(0,L6-TAX_NI_TABLES!$D$8)*ASSUMPTIONS!$E$32 | U6: =L6+S6+T6 | V6: =IF(K6="Yes",H6*I6,0) | W6: =L6-V6 | X6: =MAX(0,IF(W6<=ASSUMPTIONS!$C$18,ASSUMPTIONS!$C$15,ASSUMPTIONS!$C$15-INT((W6-ASSUMPTIONS!$C$18)/2))) | Y6: =MAX(0,W6-X6) | Z6: =MAX(0,MIN(Y6,MAX(0,ASSUMPTIONS!$C$16-X6))*ASSUMPTIONS!$E$15+MAX(0,MIN(Y6,ASSUMPTIONS!$C$17-X6)-MAX(0,ASSUMPTIONS!$C$16-X6))*ASSUMPTIONS!$E$16+MAX(0,Y6-MAX(0,ASSUMPTIONS!$C$17-X6))*ASSUMPTIONS!$E$17) | AA6: =MAX(0,MIN(W6,TAX_NI_TABLES!$D$7)-TAX_NI_TABLES!$D$6)*ASSUMPTIONS!$E$25+MAX(0,W6-TAX_NI_TABLES!$D$7)*ASSUMPTIONS!$E$26 | AB6: =V6 | AC6: =W6-Z6-AA6+AG6 | AD6: =H6*J6+IF(ASSUMPTIONS!$C$53="Reinvest in Pension",AF6*ASSUMPTIONS!$C$55,0) | AE6: =MAX(0,W6-TAX_NI_TABLES!$D$8)*ASSUMPTIONS!$E$32 | AF6: =MAX(0,T6-AE6) | AG6: =IF(ASSUMPTIONS!$C$53="Share with Employees",AF6*ASSUMPTIONS!$C$55,0) | AH6: =AF6-AG6 | AI6: =W6+AD6+AE6+AG6 | AJ6: =AC6-R6 | AK6: =IF(R6<>0,(AC6-R6)/R6,0) | AL6: =AB6-Q6 | AM6: =AI6-U6 | AN6: =AH6 | AO6: =AB6+AD6 | AP6: =ASSUMPTIONS!$C$40-AO6 | AQ6: =IF(F6<=ASSUMPTIONS!$C$15,"Personal Allowance",IF(F6<=ASSUMPTIONS!$C$16,"Basic Rate",IF(F6<=ASSUMPTIONS!$C$17,"Higher Rate","Additional Rate"))) | AR6: =IF(W6<=ASSUMPTIONS!$C$15,"Personal Allowance",IF(W6<=ASSUMPTIONS!$C$16,"Basic Rate",IF(W6<=ASSUMPTIONS!$C$17,"Higher Rate","Additional Rate"))) | AS6: =IF(AP6<0,"⚠ AA Breach!","")&IF(V6>F6,"⚠ Sacrifice>Salary","")&IF(AC6<0,"⚠ Neg Take-Home","")
A7: =EMPLOYEE_DATA!A6 | B7: =EMPLOYEE_DATA!B6&" "&EMPLOYEE_DATA!C6 | C7: =EMPLOYEE_DATA!D6 | D7: =EMPLOYEE_DATA!H6 | E7: =EMPLOYEE_DATA!I6 | F7: =EMPLOYEE_DATA!J6 | G7: =IF(EMPLOYEE_DATA!O6<>"",EMPLOYEE_DATA!O6,ASSUMPTIONS!$C$48) | H7: =IF(G7="Qualifying Earnings",MAX(0,MIN(F7,ASSUMPTIONS!$C$39)-ASSUMPTIONS!$C$38),IF(G7="Full Salary",D7,F7)) | I7: =IF(EMPLOYEE_DATA!M6="Y",EMPLOYEE_DATA!K6,ASSUMPTIONS!$C$46) | J7: =IF(EMPLOYEE_DATA!M6="Y",EMPLOYEE_DATA!L6,ASSUMPTIONS!$C$47) | K7: =IF(AND(EMPLOYEE_DATA!N6="Y",ASSUMPTIONS!$C$62="On"),"Yes","No") | L7: =F7 | M7: =MAX(0,IF(L7<=ASSUMPTIONS!$C$18,ASSUMPTIONS!$C$15,ASSUMPTIONS!$C$15-INT((L7-ASSUMPTIONS!$C$18)/2))) | N7: =MAX(0,L7-M7) | O7: =MAX(0,MIN(N7,MAX(0,ASSUMPTIONS!$C$16-M7))*ASSUMPTIONS!$E$15+MAX(0,MIN(N7,ASSUMPTIONS!$C$17-M7)-MAX(0,ASSUMPTIONS!$C$16-M7))*ASSUMPTIONS!$E$16+MAX(0,N7-MAX(0,ASSUMPTIONS!$C$17-M7))*ASSUMPTIONS!$E$17) | P7: =MAX(0,MIN(L7,TAX_NI_TABLES!$D$7)-TAX_NI_TABLES!$D$6)*ASSUMPTIONS!$E$25+MAX(0,L7-TAX_NI_TABLES!$D$7)*ASSUMPTIONS!$E$26 | Q7: =H7*I7 | R7: =L7-O7-P7-Q7 | S7: =H7*J7 | T7: =MAX(0,L7-TAX_NI_TABLES!$D$8)*ASSUMPTIONS!$E$32 | U7: =L7+S7+T7 | V7: =IF(K7="Yes",H7*I7,0) | W7: =L7-V7 | X7: =MAX(0,IF(W7<=ASSUMPTIONS!$C$18,ASSUMPTIONS!$C$15,ASSUMPTIONS!$C$15-INT((W7-ASSUMPTIONS!$C$18)/2))) | Y7: =MAX(0,W7-X7) | Z7: =MAX(0,MIN(Y7,MAX(0,ASSUMPTIONS!$C$16-X7))*ASSUMPTIONS!$E$15+MAX(0,MIN(Y7,ASSUMPTIONS!$C$17-X7)-MAX(0,ASSUMPTIONS!$C$16-X7))*ASSUMPTIONS!$E$16+MAX(0,Y7-MAX(0,ASSUMPTIONS!$C$17-X7))*ASSUMPTIONS!$E$17) | AA7: =MAX(0,MIN(W7,TAX_NI_TABLES!$D$7)-TAX_NI_TABLES!$D$6)*ASSUMPTIONS!$E$25+MAX(0,W7-TAX_NI_TABLES!$D$7)*ASSUMPTIONS!$E$26 | AB7: =V7 | AC7: =W7-Z7-AA7+AG7 | AD7: =H7*J7+IF(ASSUMPTIONS!$C$53="Reinvest in Pension",AF7*ASSUMPTIONS!$C$55,0) | AE7: =MAX(0,W7-TAX_NI_TABLES!$D$8)*ASSUMPTIONS!$E$32 | AF7: =MAX(0,T7-AE7) | AG7: =IF(ASSUMPTIONS!$C$53="Share with Employees",AF7*ASSUMPTIONS!$C$55,0) | AH7: =AF7-AG7 | AI7: =W7+AD7+AE7+AG7 | AJ7: =AC7-R7 | AK7: =IF(R7<>0,(AC7-R7)/R7,0) | AL7: =AB7-Q7 | AM7: =AI7-U7 | AN7: =AH7 | AO7: =AB7+AD7 | AP7: =ASSUMPTIONS!$C$40-AO7 | AQ7: =IF(F7<=ASSUMPTIONS!$C$15,"Personal Allowance",IF(F7<=ASSUMPTIONS!$C$16,"Basic Rate",IF(F7<=ASSUMPTIONS!$C$17,"Higher Rate","Additional Rate"))) | AR7: =IF(W7<=ASSUMPTIONS!$C$15,"Personal Allowance",IF(W7<=ASSUMPTIONS!$C$16,"Basic Rate",IF(W7<=ASSUMPTIONS!$C$17,"Higher Rate","Additional Rate"))) | AS7: =IF(AP7<0,"⚠ AA Breach!","")&IF(V7>F7,"⚠ Sacrifice>Salary","")&IF(AC7<0,"⚠ Neg Take-Home","")
A8: =EMPLOYEE_DATA!A7 | B8: =EMPLOYEE_DATA!B7&" "&EMPLOYEE_DATA!C7 | C8: =EMPLOYEE_DATA!D7 | D8: =EMPLOYEE_DATA!H7 | E8: =EMPLOYEE_DATA!I7 | F8: =EMPLOYEE_DATA!J7 | G8: =IF(EMPLOYEE_DATA!O7<>"",EMPLOYEE_DATA!O7,ASSUMPTIONS!$C$48) | H8: =IF(G8="Qualifying Earnings",MAX(0,MIN(F8,ASSUMPTIONS!$C$39)-ASSUMPTIONS!$C$38),IF(G8="Full Salary",D8,F8)) | I8: =IF(EMPLOYEE_DATA!M7="Y",EMPLOYEE_DATA!K7,ASSUMPTIONS!$C$46) | J8: =IF(EMPLOYEE_DATA!M7="Y",EMPLOYEE_DATA!L7,ASSUMPTIONS!$C$47) | K8: =IF(AND(EMPLOYEE_DATA!N7="Y",ASSUMPTIONS!$C$62="On"),"Yes","No") | L8: =F8 | M8: =MAX(0,IF(L8<=ASSUMPTIONS!$C$18,ASSUMPTIONS!$C$15,ASSUMPTIONS!$C$15-INT((L8-ASSUMPTIONS!$C$18)/2))) | N8: =MAX(0,L8-M8) | O8: =MAX(0,MIN(N8,MAX(0,ASSUMPTIONS!$C$16-M8))*ASSUMPTIONS!$E$15+MAX(0,MIN(N8,ASSUMPTIONS!$C$17-M8)-MAX(0,ASSUMPTIONS!$C$16-M8))*ASSUMPTIONS!$E$16+MAX(0,N8-MAX(0,ASSUMPTIONS!$C$17-M8))*ASSUMPTIONS!$E$17) | P8: =MAX(0,MIN(L8,TAX_NI_TABLES!$D$7)-TAX_NI_TABLES!$D$6)*ASSUMPTIONS!$E$25+MAX(0,L8-TAX_NI_TABLES!$D$7)*ASSUMPTIONS!$E$26 | Q8: =H8*I8 | R8: =L8-O8-P8-Q8 | S8: =H8*J8 | T8: =MAX(0,L8-TAX_NI_TABLES!$D$8)*ASSUMPTIONS!$E$32 | U8: =L8+S8+T8 | V8: =IF(K8="Yes",H8*I8,0) | W8: =L8-V8 | X8: =MAX(0,IF(W8<=ASSUMPTIONS!$C$18,ASSUMPTIONS!$C$15,ASSUMPTIONS!$C$15-INT((W8-ASSUMPTIONS!$C$18)/2))) | Y8: =MAX(0,W8-X8) | Z8: =MAX(0,MIN(Y8,MAX(0,ASSUMPTIONS!$C$16-X8))*ASSUMPTIONS!$E$15+MAX(0,MIN(Y8,ASSUMPTIONS!$C$17-X8)-MAX(0,ASSUMPTIONS!$C$16-X8))*ASSUMPTIONS!$E$16+MAX(0,Y8-MAX(0,ASSUMPTIONS!$C$17-X8))*ASSUMPTIONS!$E$17) | AA8: =MAX(0,MIN(W8,TAX_NI_TABLES!$D$7)-TAX_NI_TABLES!$D$6)*ASSUMPTIONS!$E$25+MAX(0,W8-TAX_NI_TABLES!$D$7)*ASSUMPTIONS!$E$26 | AB8: =V8 | AC8: =W8-Z8-AA8+AG8 | AD8: =H8*J8+IF(ASSUMPTIONS!$C$53="Reinvest in Pension",AF8*ASSUMPTIONS!$C$55,0) | AE8: =MAX(0,W8-TAX_NI_TABLES!$D$8)*ASSUMPTIONS!$E$32 | AF8: =MAX(0,T8-AE8) | AG8: =IF(ASSUMPTIONS!$C$53="Share with Employees",AF8*ASSUMPTIONS!$C$55,0) | AH8: =AF8-AG8 | AI8: =W8+AD8+AE8+AG8 | AJ8: =AC8-R8 | AK8: =IF(R8<>0,(AC8-R8)/R8,0) | AL8: =AB8-Q8 | AM8: =AI8-U8 | AN8: =AH8 | AO8: =AB8+AD8 | AP8: =ASSUMPTIONS!$C$40-AO8 | AQ8: =IF(F8<=ASSUMPTIONS!$C$15,"Personal Allowance",IF(F8<=ASSUMPTIONS!$C$16,"Basic Rate",IF(F8<=ASSUMPTIONS!$C$17,"Higher Rate","Additional Rate"))) | AR8: =IF(W8<=ASSUMPTIONS!$C$15,"Personal Allowance",IF(W8<=ASSUMPTIONS!$C$16,"Basic Rate",IF(W8<=ASSUMPTIONS!$C$17,"Higher Rate","Additional Rate"))) | AS8: =IF(AP8<0,"⚠ AA Breach!","")&IF(V8>F8,"⚠ Sacrifice>Salary","")&IF(AC8<0,"⚠ Neg Take-Home","")
A9: =EMPLOYEE_DATA!A8 | B9: =EMPLOYEE_DATA!B8&" "&EMPLOYEE_DATA!C8 | C9: =EMPLOYEE_DATA!D8 | D9: =EMPLOYEE_DATA!H8 | E9: =EMPLOYEE_DATA!I8 | F9: =EMPLOYEE_DATA!J8 | G9: =IF(EMPLOYEE_DATA!O8<>"",EMPLOYEE_DATA!O8,ASSUMPTIONS!$C$48) | H9: =IF(G9="Qualifying Earnings",MAX(0,MIN(F9,ASSUMPTIONS!$C$39)-ASSUMPTIONS!$C$38),IF(G9="Full Salary",D9,F9)) | I9: =IF(EMPLOYEE_DATA!M8="Y",EMPLOYEE_DATA!K8,ASSUMPTIONS!$C$46) | J9: =IF(EMPLOYEE_DATA!M8="Y",EMPLOYEE_DATA!L8,ASSUMPTIONS!$C$47) | K9: =IF(AND(EMPLOYEE_DATA!N8="Y",ASSUMPTIONS!$C$62="On"),"Yes","No") | L9: =F9 | M9: =MAX(0,IF(L9<=ASSUMPTIONS!$C$18,ASSUMPTIONS!$C$15,ASSUMPTIONS!$C$15-INT((L9-ASSUMPTIONS!$C$18)/2))) | N9: =MAX(0,L9-M9) | O9: =MAX(0,MIN(N9,MAX(0,ASSUMPTIONS!$C$16-M9))*ASSUMPTIONS!$E$15+MAX(0,MIN(N9,ASSUMPTIONS!$C$17-M9)-MAX(0,ASSUMPTIONS!$C$16-M9))*ASSUMPTIONS!$E$16+MAX(0,N9-MAX(0,ASSUMPTIONS!$C$17-M9))*ASSUMPTIONS!$E$17) | P9: =MAX(0,MIN(L9,TAX_NI_TABLES!$D$7)-TAX_NI_TABLES!$D$6)*ASSUMPTIONS!$E$25+MAX(0,L9-TAX_NI_TABLES!$D$7)*ASSUMPTIONS!$E$26 | Q9: =H9*I9 | R9: =L9-O9-P9-Q9 | S9: =H9*J9 | T9: =MAX(0,L9-TAX_NI_TABLES!$D$8)*ASSUMPTIONS!$E$32 | U9: =L9+S9+T9 | V9: =IF(K9="Yes",H9*I9,0) | W9: =L9-V9 | X9: =MAX(0,IF(W9<=ASSUMPTIONS!$C$18,ASSUMPTIONS!$C$15,ASSUMPTIONS!$C$15-INT((W9-ASSUMPTIONS!$C$18)/2))) | Y9: =MAX(0,W9-X9) | Z9: =MAX(0,MIN(Y9,MAX(0,ASSUMPTIONS!$C$16-X9))*ASSUMPTIONS!$E$15+MAX(0,MIN(Y9,ASSUMPTIONS!$C$17-X9)-MAX(0,ASSUMPTIONS!$C$16-X9))*ASSUMPTIONS!$E$16+MAX(0,Y9-MAX(0,ASSUMPTIONS!$C$17-X9))*ASSUMPTIONS!$E$17) | AA9: =MAX(0,MIN(W9,TAX_NI_TABLES!$D$7)-TAX_NI_TABLES!$D$6)*ASSUMPTIONS!$E$25+MAX(0,W9-TAX_NI_TABLES!$D$7)*ASSUMPTIONS!$E$26 | AB9: =V9 | AC9: =W9-Z9-AA9+AG9 | AD9: =H9*J9+IF(ASSUMPTIONS!$C$53="Reinvest in Pension",AF9*ASSUMPTIONS!$C$55,0) | AE9: =MAX(0,W9-TAX_NI_TABLES!$D$8)*ASSUMPTIONS!$E$32 | AF9: =MAX(0,T9-AE9) | AG9: =IF(ASSUMPTIONS!$C$53="Share with Employees",AF9*ASSUMPTIONS!$C$55,0) | AH9: =AF9-AG9 | AI9: =W9+AD9+AE9+AG9 | AJ9: =AC9-R9 | AK9: =IF(R9<>0,(AC9-R9)/R9,0) | AL9: =AB9-Q9 | AM9: =AI9-U9 | AN9: =AH9 | AO9: =AB9+AD9 | AP9: =ASSUMPTIONS!$C$40-AO9 | AQ9: =IF(F9<=ASSUMPTIONS!$C$15,"Personal Allowance",IF(F9<=ASSUMPTIONS!$C$16,"Basic Rate",IF(F9<=ASSUMPTIONS!$C$17,"Higher Rate","Additional Rate"))) | AR9: =IF(W9<=ASSUMPTIONS!$C$15,"Personal Allowance",IF(W9<=ASSUMPTIONS!$C$16,"Basic Rate",IF(W9<=ASSUMPTIONS!$C$17,"Higher Rate","Additional Rate"))) | AS9: =IF(AP9<0,"⚠ AA Breach!","")&IF(V9>F9,"⚠ Sacrifice>Salary","")&IF(AC9<0,"⚠ Neg Take-Home","")
A10: =EMPLOYEE_DATA!A9 | B10: =EMPLOYEE_DATA!B9&" "&EMPLOYEE_DATA!C9 | C10: =EMPLOYEE_DATA!D9 | D10: =EMPLOYEE_DATA!H9 | E10: =EMPLOYEE_DATA!I9 | F10: =EMPLOYEE_DATA!J9 | G10: =IF(EMPLOYEE_DATA!O9<>"",EMPLOYEE_DATA!O9,ASSUMPTIONS!$C$48) | H10: =IF(G10="Qualifying Earnings",MAX(0,MIN(F10,ASSUMPTIONS!$C$39)-ASSUMPTIONS!$C$38),IF(G10="Full Salary",D10,F10)) | I10: =IF(EMPLOYEE_DATA!M9="Y",EMPLOYEE_DATA!K9,ASSUMPTIONS!$C$46) | J10: =IF(EMPLOYEE_DATA!M9="Y",EMPLOYEE_DATA!L9,ASSUMPTIONS!$C$47) | K10: =IF(AND(EMPLOYEE_DATA!N9="Y",ASSUMPTIONS!$C$62="On"),"Yes","No") | L10: =F10 | M10: =MAX(0,IF(L10<=ASSUMPTIONS!$C$18,ASSUMPTIONS!$C$15,ASSUMPTIONS!$C$15-INT((L10-ASSUMPTIONS!$C$18)/2))) | N10: =MAX(0,L10-M10) | O10: =MAX(0,MIN(N10,MAX(0,ASSUMPTIONS!$C$16-M10))*ASSUMPTIONS!$E$15+MAX(0,MIN(N10,ASSUMPTIONS!$C$17-M10)-MAX(0,ASSUMPTIONS!$C$16-M10))*ASSUMPTIONS!$E$16+MAX(0,N10-MAX(0,ASSUMPTIONS!$C$17-M10))*ASSUMPTIONS!$E$17) | P10: =MAX(0,MIN(L10,TAX_NI_TABLES!$D$7)-TAX_NI_TABLES!$D$6)*ASSUMPTIONS!$E$25+MAX(0,L10-TAX_NI_TABLES!$D$7)*ASSUMPTIONS!$E$26 | Q10: =H10*I10 | R10: =L10-O10-P10-Q10 | S10: =H10*J10 | T10: =MAX(0,L10-TAX_NI_TABLES!$D$8)*ASSUMPTIONS!$E$32 | U10: =L10+S10+T10 | V10: =IF(K10="Yes",H10*I10,0) | W10: =L10-V10 | X10: =MAX(0,IF(W10<=ASSUMPTIONS!$C$18,ASSUMPTIONS!$C$15,ASSUMPTIONS!$C$15-INT((W10-ASSUMPTIONS!$C$18)/2))) | Y10: =MAX(0,W10-X10) | Z10: =MAX(0,MIN(Y10,MAX(0,ASSUMPTIONS!$C$16-X10))*ASSUMPTIONS!$E$15+MAX(0,MIN(Y10,ASSUMPTIONS!$C$17-X10)-MAX(0,ASSUMPTIONS!$C$16-X10))*ASSUMPTIONS!$E$16+MAX(0,Y10-MAX(0,ASSUMPTIONS!$C$17-X10))*ASSUMPTIONS!$E$17) | AA10: =MAX(0,MIN(W10,TAX_NI_TABLES!$D$7)-TAX_NI_TABLES!$D$6)*ASSUMPTIONS!$E$25+MAX(0,W10-TAX_NI_TABLES!$D$7)*ASSUMPTIONS!$E$26 | AB10: =V10 | AC10: =W10-Z10-AA10+AG10 | AD10: =H10*J10+IF(ASSUMPTIONS!$C$53="Reinvest in Pension",AF10*ASSUMPTIONS!$C$55,0) | AE10: =MAX(0,W10-TAX_NI_TABLES!$D$8)*ASSUMPTIONS!$E$32 | AF10: =MAX(0,T10-AE10) | AG10: =IF(ASSUMPTIONS!$C$53="Share with Employees",AF10*ASSUMPTIONS!$C$55,0) | AH10: =AF10-AG10 | AI10: =W10+AD10+AE10+AG10 | AJ10: =AC10-R10 | AK10: =IF(R10<>0,(AC10-R10)/R10,0) | AL10: =AB10-Q10 | AM10: =AI10-U10 | AN10: =AH10 | AO10: =AB10+AD10 | AP10: =ASSUMPTIONS!$C$40-AO10 | AQ10: =IF(F10<=ASSUMPTIONS!$C$15,"Personal Allowance",IF(F10<=ASSUMPTIONS!$C$16,"Basic Rate",IF(F10<=ASSUMPTIONS!$C$17,"Higher Rate","Additional Rate"))) | AR10: =IF(W10<=ASSUMPTIONS!$C$15,"Personal Allowance",IF(W10<=ASSUMPTIONS!$C$16,"Basic Rate",IF(W10<=ASSUMPTIONS!$C$17,"Higher Rate","Additional Rate"))) | AS10: =IF(AP10<0,"⚠ AA Breach!","")&IF(V10>F10,"⚠ Sacrifice>Salary","")&IF(AC10<0,"⚠ Neg Take-Home","")
A11: =EMPLOYEE_DATA!A10 | B11: =EMPLOYEE_DATA!B10&" "&EMPLOYEE_DATA!C10 | C11: =EMPLOYEE_DATA!D10 | D11: =EMPLOYEE_DATA!H10 | E11: =EMPLOYEE_DATA!I10 | F11: =EMPLOYEE_DATA!J10 | G11: =IF(EMPLOYEE_DATA!O10<>"",EMPLOYEE_DATA!O10,ASSUMPTIONS!$C$48) | H11: =IF(G11="Qualifying Earnings",MAX(0,MIN(F11,ASSUMPTIONS!$C$39)-ASSUMPTIONS!$C$38),IF(G11="Full Salary",D11,F11)) | I11: =IF(EMPLOYEE_DATA!M10="Y",EMPLOYEE_DATA!K10,ASSUMPTIONS!$C$46) | J11: =IF(EMPLOYEE_DATA!M10="Y",EMPLOYEE_DATA!L10,ASSUMPTIONS!$C$47) | K11: =IF(AND(EMPLOYEE_DATA!N10="Y",ASSUMPTIONS!$C$62="On"),"Yes","No") | L11: =F11 | M11: =MAX(0,IF(L11<=ASSUMPTIONS!$C$18,ASSUMPTIONS!$C$15,ASSUMPTIONS!$C$15-INT((L11-ASSUMPTIONS!$C$18)/2))) | N11: =MAX(0,L11-M11) | O11: =MAX(0,MIN(N11,MAX(0,ASSUMPTIONS!$C$16-M11))*ASSUMPTIONS!$E$15+MAX(0,MIN(N11,ASSUMPTIONS!$C$17-M11)-MAX(0,ASSUMPTIONS!$C$16-M11))*ASSUMPTIONS!$E$16+MAX(0,N11-MAX(0,ASSUMPTIONS!$C$17-M11))*ASSUMPTIONS!$E$17) | P11: =MAX(0,MIN(L11,TAX_NI_TABLES!$D$7)-TAX_NI_TABLES!$D$6)*ASSUMPTIONS!$E$25+MAX(0,L11-TAX_NI_TABLES!$D$7)*ASSUMPTIONS!$E$26 | Q11: =H11*I11 | R11: =L11-O11-P11-Q11 | S11: =H11*J11 | T11: =MAX(0,L11-TAX_NI_TABLES!$D$8)*ASSUMPTIONS!$E$32 | U11: =L11+S11+T11 | V11: =IF(K11="Yes",H11*I11,0) | W11: =L11-V11 | X11: =MAX(0,IF(W11<=ASSUMPTIONS!$C$18,ASSUMPTIONS!$C$15,ASSUMPTIONS!$C$15-INT((W11-ASSUMPTIONS!$C$18)/2))) | Y11: =MAX(0,W11-X11) | Z11: =MAX(0,MIN(Y11,MAX(0,ASSUMPTIONS!$C$16-X11))*ASSUMPTIONS!$E$15+MAX(0,MIN(Y11,ASSUMPTIONS!$C$17-X11)-MAX(0,ASSUMPTIONS!$C$16-X11))*ASSUMPTIONS!$E$16+MAX(0,Y11-MAX(0,ASSUMPTIONS!$C$17-X11))*ASSUMPTIONS!$E$17) | AA11: =MAX(0,MIN(W11,TAX_NI_TABLES!$D$7)-TAX_NI_TABLES!$D$6)*ASSUMPTIONS!$E$25+MAX(0,W11-TAX_NI_TABLES!$D$7)*ASSUMPTIONS!$E$26 | AB11: =V11 | AC11: =W11-Z11-AA11+AG11 | AD11: =H11*J11+IF(ASSUMPTIONS!$C$53="Reinvest in Pension",AF11*ASSUMPTIONS!$C$55,0) | AE11: =MAX(0,W11-TAX_NI_TABLES!$D$8)*ASSUMPTIONS!$E$32 | AF11: =MAX(0,T11-AE11) | AG11: =IF(ASSUMPTIONS!$C$53="Share with Employees",AF11*ASSUMPTIONS!$C$55,0) | AH11: =AF11-AG11 | AI11: =W11+AD11+AE11+AG11 | AJ11: =AC11-R11 | AK11: =IF(R11<>0,(AC11-R11)/R11,0) | AL11: =AB11-Q11 | AM11: =AI11-U11 | AN11: =AH11 | AO11: =AB11+AD11 | AP11: =ASSUMPTIONS!$C$40-AO11 | AQ11: =IF(F11<=ASSUMPTIONS!$C$15,"Personal Allowance",IF(F11<=ASSUMPTIONS!$C$16,"Basic Rate",IF(F11<=ASSUMPTIONS!$C$17,"Higher Rate","Additional Rate"))) | AR11: =IF(W11<=ASSUMPTIONS!$C$15,"Personal Allowance",IF(W11<=ASSUMPTIONS!$C$16,"Basic Rate",IF(W11<=ASSUMPTIONS!$C$17,"Higher Rate","Additional Rate"))) | AS11: =IF(AP11<0,"⚠ AA Breach!","")&IF(V11>F11,"⚠ Sacrifice>Salary","")&IF(AC11<0,"⚠ Neg Take-Home","")
A12: =EMPLOYEE_DATA!A11 | B12: =EMPLOYEE_DATA!B11&" "&EMPLOYEE_DATA!C11 | C12: =EMPLOYEE_DATA!D11 | D12: =EMPLOYEE_DATA!H11 | E12: =EMPLOYEE_DATA!I11 | F12: =EMPLOYEE_DATA!J11 | G12: =IF(EMPLOYEE_DATA!O11<>"",EMPLOYEE_DATA!O11,ASSUMPTIONS!$C$48) | H12: =IF(G12="Qualifying Earnings",MAX(0,MIN(F12,ASSUMPTIONS!$C$39)-ASSUMPTIONS!$C$38),IF(G12="Full Salary",D12,F12)) | I12: =IF(EMPLOYEE_DATA!M11="Y",EMPLOYEE_DATA!K11,ASSUMPTIONS!$C$46) | J12: =IF(EMPLOYEE_DATA!M11="Y",EMPLOYEE_DATA!L11,ASSUMPTIONS!$C$47) | K12: =IF(AND(EMPLOYEE_DATA!N11="Y",ASSUMPTIONS!$C$62="On"),"Yes","No") | L12: =F12 | M12: =MAX(0,IF(L12<=ASSUMPTIONS!$C$18,ASSUMPTIONS!$C$15,ASSUMPTIONS!$C$15-INT((L12-ASSUMPTIONS!$C$18)/2))) | N12: =MAX(0,L12-M12) | O12: =MAX(0,MIN(N12,MAX(0,ASSUMPTIONS!$C$16-M12))*ASSUMPTIONS!$E$15+MAX(0,MIN(N12,ASSUMPTIONS!$C$17-M12)-MAX(0,ASSUMPTIONS!$C$16-M12))*ASSUMPTIONS!$E$16+MAX(0,N12-MAX(0,ASSUMPTIONS!$C$17-M12))*ASSUMPTIONS!$E$17) | P12: =MAX(0,MIN(L12,TAX_NI_TABLES!$D$7)-TAX_NI_TABLES!$D$6)*ASSUMPTIONS!$E$25+MAX(0,L12-TAX_NI_TABLES!$D$7)*ASSUMPTIONS!$E$26 | Q12: =H12*I12 | R12: =L12-O12-P12-Q12 | S12: =H12*J12 | T12: =MAX(0,L12-TAX_NI_TABLES!$D$8)*ASSUMPTIONS!$E$32 | U12: =L12+S12+T12 | V12: =IF(K12="Yes",H12*I12,0) | W12: =L12-V12 | X12: =MAX(0,IF(W12<=ASSUMPTIONS!$C$18,ASSUMPTIONS!$C$15,ASSUMPTIONS!$C$15-INT((W12-ASSUMPTIONS!$C$18)/2))) | Y12: =MAX(0,W12-X12) | Z12: =MAX(0,MIN(Y12,MAX(0,ASSUMPTIONS!$C$16-X12))*ASSUMPTIONS!$E$15+MAX(0,MIN(Y12,ASSUMPTIONS!$C$17-X12)-MAX(0,ASSUMPTIONS!$C$16-X12))*ASSUMPTIONS!$E$16+MAX(0,Y12-MAX(0,ASSUMPTIONS!$C$17-X12))*ASSUMPTIONS!$E$17) | AA12: =MAX(0,MIN(W12,TAX_NI_TABLES!$D$7)-TAX_NI_TABLES!$D$6)*ASSUMPTIONS!$E$25+MAX(0,W12-TAX_NI_TABLES!$D$7)*ASSUMPTIONS!$E$26 | AB12: =V12 | AC12: =W12-Z12-AA12+AG12 | AD12: =H12*J12+IF(ASSUMPTIONS!$C$53="Reinvest in Pension",AF12*ASSUMPTIONS!$C$55,0) | AE12: =MAX(0,W12-TAX_NI_TABLES!$D$8)*ASSUMPTIONS!$E$32 | AF12: =MAX(0,T12-AE12) | AG12: =IF(ASSUMPTIONS!$C$53="Share with Employees",AF12*ASSUMPTIONS!$C$55,0) | AH12: =AF12-AG12 | AI12: =W12+AD12+AE12+AG12 | AJ12: =AC12-R12 | AK12: =IF(R12<>0,(AC12-R12)/R12,0) | AL12: =AB12-Q12 | AM12: =AI12-U12 | AN12: =AH12 | AO12: =AB12+AD12 | AP12: =ASSUMPTIONS!$C$40-AO12 | AQ12: =IF(F12<=ASSUMPTIONS!$C$15,"Personal Allowance",IF(F12<=ASSUMPTIONS!$C$16,"Basic Rate",IF(F12<=ASSUMPTIONS!$C$17,"Higher Rate","Additional Rate"))) | AR12: =IF(W12<=ASSUMPTIONS!$C$15,"Personal Allowance",IF(W12<=ASSUMPTIONS!$C$16,"Basic Rate",IF(W12<=ASSUMPTIONS!$C$17,"Higher Rate","Additional Rate"))) | AS12: =IF(AP12<0,"⚠ AA Breach!","")&IF(V12>F12,"⚠ Sacrifice>Salary","")&IF(AC12<0,"⚠ Neg Take-Home","")
A13: =EMPLOYEE_DATA!A12 | B13: =EMPLOYEE_DATA!B12&" "&EMPLOYEE_DATA!C12 | C13: =EMPLOYEE_DATA!D12 | D13: =EMPLOYEE_DATA!H12 | E13: =EMPLOYEE_DATA!I12 | F13: =EMPLOYEE_DATA!J12 | G13: =IF(EMPLOYEE_DATA!O12<>"",EMPLOYEE_DATA!O12,ASSUMPTIONS!$C$48) | H13: =IF(G13="Qualifying Earnings",MAX(0,MIN(F13,ASSUMPTIONS!$C$39)-ASSUMPTIONS!$C$38),IF(G13="Full Salary",D13,F13)) | I13: =IF(EMPLOYEE_DATA!M12="Y",EMPLOYEE_DATA!K12,ASSUMPTIONS!$C$46) | J13: =IF(EMPLOYEE_DATA!M12="Y",EMPLOYEE_DATA!L12,ASSUMPTIONS!$C$47) | K13: =IF(AND(EMPLOYEE_DATA!N12="Y",ASSUMPTIONS!$C$62="On"),"Yes","No") | L13: =F13 | M13: =MAX(0,IF(L13<=ASSUMPTIONS!$C$18,ASSUMPTIONS!$C$15,ASSUMPTIONS!$C$15-INT((L13-ASSUMPTIONS!$C$18)/2))) | N13: =MAX(0,L13-M13) | O13: =MAX(0,MIN(N13,MAX(0,ASSUMPTIONS!$C$16-M13))*ASSUMPTIONS!$E$15+MAX(0,MIN(N13,ASSUMPTIONS!$C$17-M13)-MAX(0,ASSUMPTIONS!$C$16-M13))*ASSUMPTIONS!$E$16+MAX(0,N13-MAX(0,ASSUMPTIONS!$C$17-M13))*ASSUMPTIONS!$E$17) | P13: =MAX(0,MIN(L13,TAX_NI_TABLES!$D$7)-TAX_NI_TABLES!$D$6)*ASSUMPTIONS!$E$25+MAX(0,L13-TAX_NI_TABLES!$D$7)*ASSUMPTIONS!$E$26 | Q13: =H13*I13 | R13: =L13-O13-P13-Q13 | S13: =H13*J13 | T13: =MAX(0,L13-TAX_NI_TABLES!$D$8)*ASSUMPTIONS!$E$32 | U13: =L13+S13+T13 | V13: =IF(K13="Yes",H13*I13,0) | W13: =L13-V13 | X13: =MAX(0,IF(W13<=ASSUMPTIONS!$C$18,ASSUMPTIONS!$C$15,ASSUMPTIONS!$C$15-INT((W13-ASSUMPTIONS!$C$18)/2))) | Y13: =MAX(0,W13-X13) | Z13: =MAX(0,MIN(Y13,MAX(0,ASSUMPTIONS!$C$16-X13))*ASSUMPTIONS!$E$15+MAX(0,MIN(Y13,ASSUMPTIONS!$C$17-X13)-MAX(0,ASSUMPTIONS!$C$16-X13))*ASSUMPTIONS!$E$16+MAX(0,Y13-MAX(0,ASSUMPTIONS!$C$17-X13))*ASSUMPTIONS!$E$17) | AA13: =MAX(0,MIN(W13,TAX_NI_TABLES!$D$7)-TAX_NI_TABLES!$D$6)*ASSUMPTIONS!$E$25+MAX(0,W13-TAX_NI_TABLES!$D$7)*ASSUMPTIONS!$E$26 | AB13: =V13 | AC13: =W13-Z13-AA13+AG13 | AD13: =H13*J13+IF(ASSUMPTIONS!$C$53="Reinvest in Pension",AF13*ASSUMPTIONS!$C$55,0) | AE13: =MAX(0,W13-TAX_NI_TABLES!$D$8)*ASSUMPTIONS!$E$32 | AF13: =MAX(0,T13-AE13) | AG13: =IF(ASSUMPTIONS!$C$53="Share with Employees",AF13*ASSUMPTIONS!$C$55,0) | AH13: =AF13-AG13 | AI13: =W13+AD13+AE13+AG13 | AJ13: =AC13-R13 | AK13: =IF(R13<>0,(AC13-R13)/R13,0) | AL13: =AB13-Q13 | AM13: =AI13-U13 | AN13: =AH13 | AO13: =AB13+AD13 | AP13: =ASSUMPTIONS!$C$40-AO13 | AQ13: =IF(F13<=ASSUMPTIONS!$C$15,"Personal Allowance",IF(F13<=ASSUMPTIONS!$C$16,"Basic Rate",IF(F13<=ASSUMPTIONS!$C$17,"Higher Rate","Additional Rate"))) | AR13: =IF(W13<=ASSUMPTIONS!$C$15,"Personal Allowance",IF(W13<=ASSUMPTIONS!$C$16,"Basic Rate",IF(W13<=ASSUMPTIONS!$C$17,"Higher Rate","Additional Rate"))) | AS13: =IF(AP13<0,"⚠ AA Breach!","")&IF(V13>F13,"⚠ Sacrifice>Salary","")&IF(AC13<0,"⚠ Neg Take-Home","")
A14: =EMPLOYEE_DATA!A13 | B14: =EMPLOYEE_DATA!B13&" "&EMPLOYEE_DATA!C13 | C14: =EMPLOYEE_DATA!D13 | D14: =EMPLOYEE_DATA!H13 | E14: =EMPLOYEE_DATA!I13 | F14: =EMPLOYEE_DATA!J13 | G14: =IF(EMPLOYEE_DATA!O13<>"",EMPLOYEE_DATA!O13,ASSUMPTIONS!$C$48) | H14: =IF(G14="Qualifying Earnings",MAX(0,MIN(F14,ASSUMPTIONS!$C$39)-ASSUMPTIONS!$C$38),IF(G14="Full Salary",D14,F14)) | I14: =IF(EMPLOYEE_DATA!M13="Y",EMPLOYEE_DATA!K13,ASSUMPTIONS!$C$46) | J14: =IF(EMPLOYEE_DATA!M13="Y",EMPLOYEE_DATA!L13,ASSUMPTIONS!$C$47) | K14: =IF(AND(EMPLOYEE_DATA!N13="Y",ASSUMPTIONS!$C$62="On"),"Yes","No") | L14: =F14 | M14: =MAX(0,IF(L14<=ASSUMPTIONS!$C$18,ASSUMPTIONS!$C$15,ASSUMPTIONS!$C$15-INT((L14-ASSUMPTIONS!$C$18)/2))) | N14: =MAX(0,L14-M14) | O14: =MAX(0,MIN(N14,MAX(0,ASSUMPTIONS!$C$16-M14))*ASSUMPTIONS!$E$15+MAX(0,MIN(N14,ASSUMPTIONS!$C$17-M14)-MAX(0,ASSUMPTIONS!$C$16-M14))*ASSUMPTIONS!$E$16+MAX(0,N14-MAX(0,ASSUMPTIONS!$C$17-M14))*ASSUMPTIONS!$E$17) | P14: =MAX(0,MIN(L14,TAX_NI_TABLES!$D$7)-TAX_NI_TABLES!$D$6)*ASSUMPTIONS!$E$25+MAX(0,L14-TAX_NI_TABLES!$D$7)*ASSUMPTIONS!$E$26 | Q14: =H14*I14 | R14: =L14-O14-P14-Q14 | S14: =H14*J14 | T14: =MAX(0,L14-TAX_NI_TABLES!$D$8)*ASSUMPTIONS!$E$32 | U14: =L14+S14+T14 | V14: =IF(K14="Yes",H14*I14,0) | W14: =L14-V14 | X14: =MAX(0,IF(W14<=ASSUMPTIONS!$C$18,ASSUMPTIONS!$C$15,ASSUMPTIONS!$C$15-INT((W14-ASSUMPTIONS!$C$18)/2))) | Y14: =MAX(0,W14-X14) | Z14: =MAX(0,MIN(Y14,MAX(0,ASSUMPTIONS!$C$16-X14))*ASSUMPTIONS!$E$15+MAX(0,MIN(Y14,ASSUMPTIONS!$C$17-X14)-MAX(0,ASSUMPTIONS!$C$16-X14))*ASSUMPTIONS!$E$16+MAX(0,Y14-MAX(0,ASSUMPTIONS!$C$17-X14))*ASSUMPTIONS!$E$17) | AA14: =MAX(0,MIN(W14,TAX_NI_TABLES!$D$7)-TAX_NI_TABLES!$D$6)*ASSUMPTIONS!$E$25+MAX(0,W14-TAX_NI_TABLES!$D$7)*ASSUMPTIONS!$E$26 | AB14: =V14 | AC14: =W14-Z14-AA14+AG14 | AD14: =H14*J14+IF(ASSUMPTIONS!$C$53="Reinvest in Pension",AF14*ASSUMPTIONS!$C$55,0) | AE14: =MAX(0,W14-TAX_NI_TABLES!$D$8)*ASSUMPTIONS!$E$32 | AF14: =MAX(0,T14-AE14) | AG14: =IF(ASSUMPTIONS!$C$53="Share with Employees",AF14*ASSUMPTIONS!$C$55,0) | AH14: =AF14-AG14 | AI14: =W14+AD14+AE14+AG14 | AJ14: =AC14-R14 | AK14: =IF(R14<>0,(AC14-R14)/R14,0) | AL14: =AB14-Q14 | AM14: =AI14-U14 | AN14: =AH14 | AO14: =AB14+AD14 | AP14: =ASSUMPTIONS!$C$40-AO14 | AQ14: =IF(F14<=ASSUMPTIONS!$C$15,"Personal Allowance",IF(F14<=ASSUMPTIONS!$C$16,"Basic Rate",IF(F14<=ASSUMPTIONS!$C$17,"Higher Rate","Additional Rate"))) | AR14: =IF(W14<=ASSUMPTIONS!$C$15,"Personal Allowance",IF(W14<=ASSUMPTIONS!$C$16,"Basic Rate",IF(W14<=ASSUMPTIONS!$C$17,"Higher Rate","Additional Rate"))) | AS14: =IF(AP14<0,"⚠ AA Breach!","")&IF(V14>F14,"⚠ Sacrifice>Salary","")&IF(AC14<0,"⚠ Neg Take-Home","")
A15: =EMPLOYEE_DATA!A14 | B15: =EMPLOYEE_DATA!B14&" "&EMPLOYEE_DATA!C14 | C15: =EMPLOYEE_DATA!D14 | D15: =EMPLOYEE_DATA!H14 | E15: =EMPLOYEE_DATA!I14 | F15: =EMPLOYEE_DATA!J14 | G15: =IF(EMPLOYEE_DATA!O14<>"",EMPLOYEE_DATA!O14,ASSUMPTIONS!$C$48) | H15: =IF(G15="Qualifying Earnings",MAX(0,MIN(F15,ASSUMPTIONS!$C$39)-ASSUMPTIONS!$C$38),IF(G15="Full Salary",D15,F15)) | I15: =IF(EMPLOYEE_DATA!M14="Y",EMPLOYEE_DATA!K14,ASSUMPTIONS!$C$46) | J15: =IF(EMPLOYEE_DATA!M14="Y",EMPLOYEE_DATA!L14,ASSUMPTIONS!$C$47) | K15: =IF(AND(EMPLOYEE_DATA!N14="Y",ASSUMPTIONS!$C$62="On"),"Yes","No") | L15: =F15 | M15: =MAX(0,IF(L15<=ASSUMPTIONS!$C$18,ASSUMPTIONS!$C$15,ASSUMPTIONS!$C$15-INT((L15-ASSUMPTIONS!$C$18)/2))) | N15: =MAX(0,L15-M15) | O15: =MAX(0,MIN(N15,MAX(0,ASSUMPTIONS!$C$16-M15))*ASSUMPTIONS!$E$15+MAX(0,MIN(N15,ASSUMPTIONS!$C$17-M15)-MAX(0,ASSUMPTIONS!$C$16-M15))*ASSUMPTIONS!$E$16+MAX(0,N15-MAX(0,ASSUMPTIONS!$C$17-M15))*ASSUMPTIONS!$E$17) | P15: =MAX(0,MIN(L15,TAX_NI_TABLES!$D$7)-TAX_NI_TABLES!$D$6)*ASSUMPTIONS!$E$25+MAX(0,L15-TAX_NI_TABLES!$D$7)*ASSUMPTIONS!$E$26 | Q15: =H15*I15 | R15: =L15-O15-P15-Q15 | S15: =H15*J15 | T15: =MAX(0,L15-TAX_NI_TABLES!$D$8)*ASSUMPTIONS!$E$32 | U15: =L15+S15+T15 | V15: =IF(K15="Yes",H15*I15,0) | W15: =L15-V15 | X15: =MAX(0,IF(W15<=ASSUMPTIONS!$C$18,ASSUMPTIONS!$C$15,ASSUMPTIONS!$C$15-INT((W15-ASSUMPTIONS!$C$18)/2))) | Y15: =MAX(0,W15-X15) | Z15: =MAX(0,MIN(Y15,MAX(0,ASSUMPTIONS!$C$16-X15))*ASSUMPTIONS!$E$15+MAX(0,MIN(Y15,ASSUMPTIONS!$C$17-X15)-MAX(0,ASSUMPTIONS!$C$16-X15))*ASSUMPTIONS!$E$16+MAX(0,Y15-MAX(0,ASSUMPTIONS!$C$17-X15))*ASSUMPTIONS!$E$17) | AA15: =MAX(0,MIN(W15,TAX_NI_TABLES!$D$7)-TAX_NI_TABLES!$D$6)*ASSUMPTIONS!$E$25+MAX(0,W15-TAX_NI_TABLES!$D$7)*ASSUMPTIONS!$E$26 | AB15: =V15 | AC15: =W15-Z15-AA15+AG15 | AD15: =H15*J15+IF(ASSUMPTIONS!$C$53="Reinvest in Pension",AF15*ASSUMPTIONS!$C$55,0) | AE15: =MAX(0,W15-TAX_NI_TABLES!$D$8)*ASSUMPTIONS!$E$32 | AF15: =MAX(0,T15-AE15) | AG15: =IF(ASSUMPTIONS!$C$53="Share with Employees",AF15*ASSUMPTIONS!$C$55,0) | AH15: =AF15-AG15 | AI15: =W15+AD15+AE15+AG15 | AJ15: =AC15-R15 | AK15: =IF(R15<>0,(AC15-R15)/R15,0) | AL15: =AB15-Q15 | AM15: =AI15-U15 | AN15: =AH15 | AO15: =AB15+AD15 | AP15: =ASSUMPTIONS!$C$40-AO15 | AQ15: =IF(F15<=ASSUMPTIONS!$C$15,"Personal Allowance",IF(F15<=ASSUMPTIONS!$C$16,"Basic Rate",IF(F15<=ASSUMPTIONS!$C$17,"Higher Rate","Additional Rate"))) | AR15: =IF(W15<=ASSUMPTIONS!$C$15,"Personal Allowance",IF(W15<=ASSUMPTIONS!$C$16,"Basic Rate",IF(W15<=ASSUMPTIONS!$C$17,"Higher Rate","Additional Rate"))) | AS15: =IF(AP15<0,"⚠ AA Breach!","")&IF(V15>F15,"⚠ Sacrifice>Salary","")&IF(AC15<0,"⚠ Neg Take-Home","")
... A28: =EMPLOYEE_DATA!A27 | B28: =EMPLOYEE_DATA!B27&" "&EMPLOYEE_DATA!C27 | C28: =EMPLOYEE_DATA!D27 | D28: =EMPLOYEE_DATA!H27 | E28: =EMPLOYEE_DATA!I27 | F28: =EMPLOYEE_DATA!J27 | G28: =IF(EMPLOYEE_DATA!O27<>"",EMPLOYEE_DATA!O27,ASSUMPTIONS!$C$48) | H28: =IF(G28="Qualifying Earnings",MAX(0,MIN(F28,ASSUMPTIONS!$C$39)-ASSUMPTIONS!$C$38),IF(G28="Full Salary",D28,F28)) | I28: =IF(EMPLOYEE_DATA!M27="Y",EMPLOYEE_DATA!K27,ASSUMPTIONS!$C$46) | J28: =IF(EMPLOYEE_DATA!M27="Y",EMPLOYEE_DATA!L27,ASSUMPTIONS!$C$47) | K28: =IF(AND(EMPLOYEE_DATA!N27="Y",ASSUMPTIONS!$C$62="On"),"Yes","No") | L28: =F28 | M28: =MAX(0,IF(L28<=ASSUMPTIONS!$C$18,ASSUMPTIONS!$C$15,ASSUMPTIONS!$C$15-INT((L28-ASSUMPTIONS!$C$18)/2))) | N28: =MAX(0,L28-M28) | O28: =MAX(0,MIN(N28,MAX(0,ASSUMPTIONS!$C$16-M28))*ASSUMPTIONS!$E$15+MAX(0,MIN(N28,ASSUMPTIONS!$C$17-M28)-MAX(0,ASSUMPTIONS!$C$16-M28))*ASSUMPTIONS!$E$16+MAX(0,N28-MAX(0,ASSUMPTIONS!$C$17-M28))*ASSUMPTIONS!$E$17) | P28: =MAX(0,MIN(L28,TAX_NI_TABLES!$D$7)-TAX_NI_TABLES!$D$6)*ASSUMPTIONS!$E$25+MAX(0,L28-TAX_NI_TABLES!$D$7)*ASSUMPTIONS!$E$26 | Q28: =H28*I28 | R28: =L28-O28-P28-Q28 | S28: =H28*J28 | T28: =MAX(0,L28-TAX_NI_TABLES!$D$8)*ASSUMPTIONS!$E$32 | U28: =L28+S28+T28 | V28: =IF(K28="Yes",H28*I28,0) | W28: =L28-V28 | X28: =MAX(0,IF(W28<=ASSUMPTIONS!$C$18,ASSUMPTIONS!$C$15,ASSUMPTIONS!$C$15-INT((W28-ASSUMPTIONS!$C$18)/2))) | Y28: =MAX(0,W28-X28) | Z28: =MAX(0,MIN(Y28,MAX(0,ASSUMPTIONS!$C$16-X28))*ASSUMPTIONS!$E$15+MAX(0,MIN(Y28,ASSUMPTIONS!$C$17-X28)-MAX(0,ASSUMPTIONS!$C$16-X28))*ASSUMPTIONS!$E$16+MAX(0,Y28-MAX(0,ASSUMPTIONS!$C$17-X28))*ASSUMPTIONS!$E$17) | AA28: =MAX(0,MIN(W28,TAX_NI_TABLES!$D$7)-TAX_NI_TABLES!$D$6)*ASSUMPTIONS!$E$25+MAX(0,W28-TAX_NI_TABLES!$D$7)*ASSUMPTIONS!$E$26 | AB28: =V28 | AC28: =W28-Z28-AA28+AG28 | AD28: =H28*J28+IF(ASSUMPTIONS!$C$53="Reinvest in Pension",AF28*ASSUMPTIONS!$C$55,0) | AE28: =MAX(0,W28-TAX_NI_TABLES!$D$8)*ASSUMPTIONS!$E$32 | AF28: =MAX(0,T28-AE28) | AG28: =IF(ASSUMPTIONS!$C$53="Share with Employees",AF28*ASSUMPTIONS!$C$55,0) | AH28: =AF28-AG28 | AI28: =W28+AD28+AE28+AG28 | AJ28: =AC28-R28 | AK28: =IF(R28<>0,(AC28-R28)/R28,0) | AL28: =AB28-Q28 | AM28: =AI28-U28 | AN28: =AH28 | AO28: =AB28+AD28 | AP28: =ASSUMPTIONS!$C$40-AO28 | AQ28: =IF(F28<=ASSUMPTIONS!$C$15,"Personal Allowance",IF(F28<=ASSUMPTIONS!$C$16,"Basic Rate",IF(F28<=ASSUMPTIONS!$C$17,"Higher Rate","Additional Rate"))) | AR28: =IF(W28<=ASSUMPTIONS!$C$15,"Personal Allowance",IF(W28<=ASSUMPTIONS!$C$16,"Basic Rate",IF(W28<=ASSUMPTIONS!$C$17,"Higher Rate","Additional Rate"))) | AS28: =IF(AP28<0,"⚠ AA Breach!","")&IF(V28>F28,"⚠ Sacrifice>Salary","")&IF(AC28<0,"⚠ Neg Take-Home","")
A29: COMPANY TOTALS | D29: =SUM(D4:D28) | E29: =SUM(E4:E28) | F29: =SUM(F4:F28) | H29: =SUM(H4:H28) | L29: =SUM(L4:L28) | O29: =SUM(O4:O28) | P29: =SUM(P4:P28) | Q29: =SUM(Q4:Q28) | R29: =SUM(R4:R28) | S29: =SUM(S4:S28) | T29: =SUM(T4:T28) | U29: =SUM(U4:U28) | V29: =SUM(V4:V28) | W29: =SUM(W4:W28) | Z29: =SUM(Z4:Z28) | AA29: =SUM(AA4:AA28) | AB29: =SUM(AB4:AB28) | AC29: =SUM(AC4:AC28) | AD29: =SUM(AD4:AD28) | AE29: =SUM(AE4:AE28) | AF29: =SUM(AF4:AF28) | AG29: =SUM(AG4:AG28) | ... AJ29: =SUM(AJ4:AJ28) | AK29: =IFERROR(SUM(AJ4:AJ28)/SUM(R4:R28),0) | AL29: =SUM(AL4:AL28) | AM29: =SUM(AM4:AM28) | AN29: =SUM(AN4:AN28) | AO29: =SUM(AO4:AO28)

Sheet EMPLOYEE_IMPACT
A1: EMPLOYEE IMPACT ANALYSIS — Per Employee View of Salary Sacrifice Benefits
A3: Emp ID | B3: Name | C3: Department | D3: Tax Band (Pre) | E3: Tax Band (Post) | F3: Basic Salary £ | G3: Take-Home Pre £ | H3: Take-Home Post £ | I3: Take-Home Change £ | J3: Take-Home Chg % | K3: EE Pension Pre £ | L3: EE Pension Post £ | M3: EE Pension Change £ | N3: PAYE Tax Pre £ | O3: PAYE Tax Post £ | P3: Tax Saving £ | Q3: EE NI Pre £ | R3: EE NI Post £ | S3: EE NI Saving £ | T3: NI Share from ER £ | U3: Total Pension £ (EE+ER Post) | V3: AA Remaining £ | W3: Net Benefit £ (vs Pre)
A4: =CALC_ENGINE!A4 | B4: =CALC_ENGINE!B4 | C4: =CALC_ENGINE!C4 | D4: =CALC_ENGINE!AQ4 | E4: =CALC_ENGINE!AR4 | F4: =CALC_ENGINE!D4 | G4: =CALC_ENGINE!R4 | H4: =CALC_ENGINE!AC4 | I4: =CALC_ENGINE!AJ4 | J4: =CALC_ENGINE!AK4 | K4: =CALC_ENGINE!Q4 | L4: =CALC_ENGINE!AB4 | M4: =CALC_ENGINE!AL4 | N4: =CALC_ENGINE!O4 | O4: =CALC_ENGINE!Z4 | P4: =CALC_ENGINE!O4-CALC_ENGINE!Z4 | Q4: =CALC_ENGINE!P4 | R4: =CALC_ENGINE!AA4 | S4: =CALC_ENGINE!P4-CALC_ENGINE!AA4 | T4: =CALC_ENGINE!AG4 | U4: =CALC_ENGINE!AO4 | V4: =CALC_ENGINE!AP4 | W4: =CALC_ENGINE!AJ4+CALC_ENGINE!AL4+CALC_ENGINE!AG4
A5: =CALC_ENGINE!A5 | B5: =CALC_ENGINE!B5 | C5: =CALC_ENGINE!C5 | D5: =CALC_ENGINE!AQ5 | E5: =CALC_ENGINE!AR5 | F5: =CALC_ENGINE!D5 | G5: =CALC_ENGINE!R5 | H5: =CALC_ENGINE!AC5 | I5: =CALC_ENGINE!AJ5 | J5: =CALC_ENGINE!AK5 | K5: =CALC_ENGINE!Q5 | L5: =CALC_ENGINE!AB5 | M5: =CALC_ENGINE!AL5 | N5: =CALC_ENGINE!O5 | O5: =CALC_ENGINE!Z5 | P5: =CALC_ENGINE!O5-CALC_ENGINE!Z5 | Q5: =CALC_ENGINE!P5 | R5: =CALC_ENGINE!AA5 | S5: =CALC_ENGINE!P5-CALC_ENGINE!AA5 | T5: =CALC_ENGINE!AG5 | U5: =CALC_ENGINE!AO5 | V5: =CALC_ENGINE!AP5 | W5: =CALC_ENGINE!AJ5+CALC_ENGINE!AL5+CALC_ENGINE!AG5
A6: =CALC_ENGINE!A6 | B6: =CALC_ENGINE!B6 | C6: =CALC_ENGINE!C6 | D6: =CALC_ENGINE!AQ6 | E6: =CALC_ENGINE!AR6 | F6: =CALC_ENGINE!D6 | G6: =CALC_ENGINE!R6 | H6: =CALC_ENGINE!AC6 | I6: =CALC_ENGINE!AJ6 | J6: =CALC_ENGINE!AK6 | K6: =CALC_ENGINE!Q6 | L6: =CALC_ENGINE!AB6 | M6: =CALC_ENGINE!AL6 | N6: =CALC_ENGINE!O6 | O6: =CALC_ENGINE!Z6 | P6: =CALC_ENGINE!O6-CALC_ENGINE!Z6 | Q6: =CALC_ENGINE!P6 | R6: =CALC_ENGINE!AA6 | S6: =CALC_ENGINE!P6-CALC_ENGINE!AA6 | T6: =CALC_ENGINE!AG6 | U6: =CALC_ENGINE!AO6 | V6: =CALC_ENGINE!AP6 | W6: =CALC_ENGINE!AJ6+CALC_ENGINE!AL6+CALC_ENGINE!AG6
A7: =CALC_ENGINE!A7 | B7: =CALC_ENGINE!B7 | C7: =CALC_ENGINE!C7 | D7: =CALC_ENGINE!AQ7 | E7: =CALC_ENGINE!AR7 | F7: =CALC_ENGINE!D7 | G7: =CALC_ENGINE!R7 | H7: =CALC_ENGINE!AC7 | I7: =CALC_ENGINE!AJ7 | J7: =CALC_ENGINE!AK7 | K7: =CALC_ENGINE!Q7 | L7: =CALC_ENGINE!AB7 | M7: =CALC_ENGINE!AL7 | N7: =CALC_ENGINE!O7 | O7: =CALC_ENGINE!Z7 | P7: =CALC_ENGINE!O7-CALC_ENGINE!Z7 | Q7: =CALC_ENGINE!P7 | R7: =CALC_ENGINE!AA7 | S7: =CALC_ENGINE!P7-CALC_ENGINE!AA7 | T7: =CALC_ENGINE!AG7 | U7: =CALC_ENGINE!AO7 | V7: =CALC_ENGINE!AP7 | W7: =CALC_ENGINE!AJ7+CALC_ENGINE!AL7+CALC_ENGINE!AG7
A8: =CALC_ENGINE!A8 | B8: =CALC_ENGINE!B8 | C8: =CALC_ENGINE!C8 | D8: =CALC_ENGINE!AQ8 | E8: =CALC_ENGINE!AR8 | F8: =CALC_ENGINE!D8 | G8: =CALC_ENGINE!R8 | H8: =CALC_ENGINE!AC8 | I8: =CALC_ENGINE!AJ8 | J8: =CALC_ENGINE!AK8 | K8: =CALC_ENGINE!Q8 | L8: =CALC_ENGINE!AB8 | M8: =CALC_ENGINE!AL8 | N8: =CALC_ENGINE!O8 | O8: =CALC_ENGINE!Z8 | P8: =CALC_ENGINE!O8-CALC_ENGINE!Z8 | Q8: =CALC_ENGINE!P8 | R8: =CALC_ENGINE!AA8 | S8: =CALC_ENGINE!P8-CALC_ENGINE!AA8 | T8: =CALC_ENGINE!AG8 | U8: =CALC_ENGINE!AO8 | V8: =CALC_ENGINE!AP8 | W8: =CALC_ENGINE!AJ8+CALC_ENGINE!AL8+CALC_ENGINE!AG8
A9: =CALC_ENGINE!A9 | B9: =CALC_ENGINE!B9 | C9: =CALC_ENGINE!C9 | D9: =CALC_ENGINE!AQ9 | E9: =CALC_ENGINE!AR9 | F9: =CALC_ENGINE!D9 | G9: =CALC_ENGINE!R9 | H9: =CALC_ENGINE!AC9 | I9: =CALC_ENGINE!AJ9 | J9: =CALC_ENGINE!AK9 | K9: =CALC_ENGINE!Q9 | L9: =CALC_ENGINE!AB9 | M9: =CALC_ENGINE!AL9 | N9: =CALC_ENGINE!O9 | O9: =CALC_ENGINE!Z9 | P9: =CALC_ENGINE!O9-CALC_ENGINE!Z9 | Q9: =CALC_ENGINE!P9 | R9: =CALC_ENGINE!AA9 | S9: =CALC_ENGINE!P9-CALC_ENGINE!AA9 | T9: =CALC_ENGINE!AG9 | U9: =CALC_ENGINE!AO9 | V9: =CALC_ENGINE!AP9 | W9: =CALC_ENGINE!AJ9+CALC_ENGINE!AL9+CALC_ENGINE!AG9
A10: =CALC_ENGINE!A10 | B10: =CALC_ENGINE!B10 | C10: =CALC_ENGINE!C10 | D10: =CALC_ENGINE!AQ10 | E10: =CALC_ENGINE!AR10 | F10: =CALC_ENGINE!D10 | G10: =CALC_ENGINE!R10 | H10: =CALC_ENGINE!AC10 | I10: =CALC_ENGINE!AJ10 | J10: =CALC_ENGINE!AK10 | K10: =CALC_ENGINE!Q10 | L10: =CALC_ENGINE!AB10 | M10: =CALC_ENGINE!AL10 | N10: =CALC_ENGINE!O10 | O10: =CALC_ENGINE!Z10 | P10: =CALC_ENGINE!O10-CALC_ENGINE!Z10 | Q10: =CALC_ENGINE!P10 | R10: =CALC_ENGINE!AA10 | S10: =CALC_ENGINE!P10-CALC_ENGINE!AA10 | T10: =CALC_ENGINE!AG10 | U10: =CALC_ENGINE!AO10 | V10: =CALC_ENGINE!AP10 | W10: =CALC_ENGINE!AJ10+CALC_ENGINE!AL10+CALC_ENGINE!AG10
A11: =CALC_ENGINE!A11 | B11: =CALC_ENGINE!B11 | C11: =CALC_ENGINE!C11 | D11: =CALC_ENGINE!AQ11 | E11: =CALC_ENGINE!AR11 | F11: =CALC_ENGINE!D11 | G11: =CALC_ENGINE!R11 | H11: =CALC_ENGINE!AC11 | I11: =CALC_ENGINE!AJ11 | J11: =CALC_ENGINE!AK11 | K11: =CALC_ENGINE!Q11 | L11: =CALC_ENGINE!AB11 | M11: =CALC_ENGINE!AL11 | N11: =CALC_ENGINE!O11 | O11: =CALC_ENGINE!Z11 | P11: =CALC_ENGINE!O11-CALC_ENGINE!Z11 | Q11: =CALC_ENGINE!P11 | R11: =CALC_ENGINE!AA11 | S11: =CALC_ENGINE!P11-CALC_ENGINE!AA11 | T11: =CALC_ENGINE!AG11 | U11: =CALC_ENGINE!AO11 | V11: =CALC_ENGINE!AP11 | W11: =CALC_ENGINE!AJ11+CALC_ENGINE!AL11+CALC_ENGINE!AG11
A12: =CALC_ENGINE!A12 | B12: =CALC_ENGINE!B12 | C12: =CALC_ENGINE!C12 | D12: =CALC_ENGINE!AQ12 | E12: =CALC_ENGINE!AR12 | F12: =CALC_ENGINE!D12 | G12: =CALC_ENGINE!R12 | H12: =CALC_ENGINE!AC12 | I12: =CALC_ENGINE!AJ12 | J12: =CALC_ENGINE!AK12 | K12: =CALC_ENGINE!Q12 | L12: =CALC_ENGINE!AB12 | M12: =CALC_ENGINE!AL12 | N12: =CALC_ENGINE!O12 | O12: =CALC_ENGINE!Z12 | P12: =CALC_ENGINE!O12-CALC_ENGINE!Z12 | Q12: =CALC_ENGINE!P12 | R12: =CALC_ENGINE!AA12 | S12: =CALC_ENGINE!P12-CALC_ENGINE!AA12 | T12: =CALC_ENGINE!AG12 | U12: =CALC_ENGINE!AO12 | V12: =CALC_ENGINE!AP12 | W12: =CALC_ENGINE!AJ12+CALC_ENGINE!AL12+CALC_ENGINE!AG12
A13: =CALC_ENGINE!A13 | B13: =CALC_ENGINE!B13 | C13: =CALC_ENGINE!C13 | D13: =CALC_ENGINE!AQ13 | E13: =CALC_ENGINE!AR13 | F13: =CALC_ENGINE!D13 | G13: =CALC_ENGINE!R13 | H13: =CALC_ENGINE!AC13 | I13: =CALC_ENGINE!AJ13 | J13: =CALC_ENGINE!AK13 | K13: =CALC_ENGINE!Q13 | L13: =CALC_ENGINE!AB13 | M13: =CALC_ENGINE!AL13 | N13: =CALC_ENGINE!O13 | O13: =CALC_ENGINE!Z13 | P13: =CALC_ENGINE!O13-CALC_ENGINE!Z13 | Q13: =CALC_ENGINE!P13 | R13: =CALC_ENGINE!AA13 | S13: =CALC_ENGINE!P13-CALC_ENGINE!AA13 | T13: =CALC_ENGINE!AG13 | U13: =CALC_ENGINE!AO13 | V13: =CALC_ENGINE!AP13 | W13: =CALC_ENGINE!AJ13+CALC_ENGINE!AL13+CALC_ENGINE!AG13
A14: =CALC_ENGINE!A14 | B14: =CALC_ENGINE!B14 | C14: =CALC_ENGINE!C14 | D14: =CALC_ENGINE!AQ14 | E14: =CALC_ENGINE!AR14 | F14: =CALC_ENGINE!D14 | G14: =CALC_ENGINE!R14 | H14: =CALC_ENGINE!AC14 | I14: =CALC_ENGINE!AJ14 | J14: =CALC_ENGINE!AK14 | K14: =CALC_ENGINE!Q14 | L14: =CALC_ENGINE!AB14 | M14: =CALC_ENGINE!AL14 | N14: =CALC_ENGINE!O14 | O14: =CALC_ENGINE!Z14 | P14: =CALC_ENGINE!O14-CALC_ENGINE!Z14 | Q14: =CALC_ENGINE!P14 | R14: =CALC_ENGINE!AA14 | S14: =CALC_ENGINE!P14-CALC_ENGINE!AA14 | T14: =CALC_ENGINE!AG14 | U14: =CALC_ENGINE!AO14 | V14: =CALC_ENGINE!AP14 | W14: =CALC_ENGINE!AJ14+CALC_ENGINE!AL14+CALC_ENGINE!AG14
A15: =CALC_ENGINE!A15 | B15: =CALC_ENGINE!B15 | C15: =CALC_ENGINE!C15 | D15: =CALC_ENGINE!AQ15 | E15: =CALC_ENGINE!AR15 | F15: =CALC_ENGINE!D15 | G15: =CALC_ENGINE!R15 | H15: =CALC_ENGINE!AC15 | I15: =CALC_ENGINE!AJ15 | J15: =CALC_ENGINE!AK15 | K15: =CALC_ENGINE!Q15 | L15: =CALC_ENGINE!AB15 | M15: =CALC_ENGINE!AL15 | N15: =CALC_ENGINE!O15 | O15: =CALC_ENGINE!Z15 | P15: =CALC_ENGINE!O15-CALC_ENGINE!Z15 | Q15: =CALC_ENGINE!P15 | R15: =CALC_ENGINE!AA15 | S15: =CALC_ENGINE!P15-CALC_ENGINE!AA15 | T15: =CALC_ENGINE!AG15 | U15: =CALC_ENGINE!AO15 | V15: =CALC_ENGINE!AP15 | W15: =CALC_ENGINE!AJ15+CALC_ENGINE!AL15+CALC_ENGINE!AG15
... A28: =CALC_ENGINE!A28 | B28: =CALC_ENGINE!B28 | C28: =CALC_ENGINE!C28 | D28: =CALC_ENGINE!AQ28 | E28: =CALC_ENGINE!AR28 | F28: =CALC_ENGINE!D28 | G28: =CALC_ENGINE!R28 | H28: =CALC_ENGINE!AC28 | I28: =CALC_ENGINE!AJ28 | J28: =CALC_ENGINE!AK28 | K28: =CALC_ENGINE!Q28 | L28: =CALC_ENGINE!AB28 | M28: =CALC_ENGINE!AL28 | N28: =CALC_ENGINE!O28 | O28: =CALC_ENGINE!Z28 | P28: =CALC_ENGINE!O28-CALC_ENGINE!Z28 | Q28: =CALC_ENGINE!P28 | R28: =CALC_ENGINE!AA28 | S28: =CALC_ENGINE!P28-CALC_ENGINE!AA28 | T28: =CALC_ENGINE!AG28 | U28: =CALC_ENGINE!AO28 | V28: =CALC_ENGINE!AP28 | W28: =CALC_ENGINE!AJ28+CALC_ENGINE!AL28+CALC_ENGINE!AG28
A29: COMPANY TOTALS | F29: =SUM(F4:F28) | G29: =SUM(G4:G28) | H29: =SUM(H4:H28) | I29: =SUM(I4:I28) | J29: =IFERROR(I29/G29,0) | K29: =SUM(K4:K28) | L29: =SUM(L4:L28) | M29: =SUM(M4:M28) | N29: =SUM(N4:N28) | O29: =SUM(O4:O28) | P29: =SUM(P4:P28) | Q29: =SUM(Q4:Q28) | R29: =SUM(R4:R28) | ... U29: =SUM(U4:U28) | W29: =SUM(W4:W28)

Sheet EMPLOYER_ANALYSIS
A1: EMPLOYER COST ANALYSIS — Total Company Impact of Salary Sacrifice
B3: COMPANY-WIDE PAYROLL SUMMARY
B4: Metric | C4: Pre-Sacrifice £ | D4: Post-Sacrifice £ | E4: Change £
B5: Total Gross Payroll | C5: =CALC_ENGINE!D29 | D5: =CALC_ENGINE!W29 | E5: =D5-C5
B6: Total PAYE Tax | C6: =CALC_ENGINE!O29 | D6: =CALC_ENGINE!Z29 | E6: =D6-C6
B7: Total Employee NI | C7: =CALC_ENGINE!P29 | D7: =CALC_ENGINE!AA29 | E7: =D7-C7
B8: Total Employee Pension (EE) | C8: =CALC_ENGINE!Q29 | D8: =CALC_ENGINE!AB29 | E8: =D8-C8
B9: Total Employee Take-Home | C9: =CALC_ENGINE!R29 | D9: =CALC_ENGINE!AC29 | E9: =D9-C9
B10: Total Employer Pension (ER) | C10: =CALC_ENGINE!S29 | D10: =CALC_ENGINE!AD29 | E10: =D10-C10
B11: Total Employer NI | C11: =CALC_ENGINE!T29 | D11: =CALC_ENGINE!AE29 | E11: =D11-C11
B12: Total Employer Cost | C12: =CALC_ENGINE!U29 | D12: =CALC_ENGINE!AI29 | E12: =D12-C12
B13: Total ER NI Saving | C13: N/A | D13: =CALC_ENGINE!AF29 | E13: =D13
B14: NI Saving Shared to EEs | C14: N/A | D14: =CALC_ENGINE!AG29 | E14: =D14
B15: NI Saving Retained/Reinvest | C15: N/A | D15: =CALC_ENGINE!AH29 | E15: =D15
B16: Total Pension Into Scheme | C16: =CALC_ENGINE!Q29+CALC_ENGINE!S29 | D16: =CALC_ENGINE!AB29+CALC_ENGINE!AD29 | E16: =D16-C16
B19: EMPLOYER NI SAVING BREAKDOWN
B20: Metric | C20: Annual £ | D20: Monthly £ | E20: Per Employee Avg £
B21: Gross ER NI Saving | C21: =CALC_ENGINE!AF29 | D21: =C21/12 | E21: =C21/25
B22: NI Saving → Employees | C22: =CALC_ENGINE!AG29 | D22: =C22/12 | E22: =C22/25
B23: NI Saving → Retained/Reinvest | C23: =CALC_ENGINE!AH29 | D23: =C23/12 | E23: =C23/25
B24: Net ER NI Saving (retained) | C24: =CALC_ENGINE!AH29 | D24: =C24/12 | E24: =C24/25
B27: EMPLOYMENT ALLOWANCE IMPACT
B28: Employment Allowance Entitlement £ | C28: =ASSUMPTIONS!$C$33
B29: ER NI Pre-Sacrifice £ | C29: =CALC_ENGINE!T29
B30: ER NI Post-Sacrifice £ | C30: =CALC_ENGINE!AE29
B31: EA Applied (Post) £ | C31: =MIN(ASSUMPTIONS!$C$33,CALC_ENGINE!AE29)
B32: Net ER NI After EA £ | C32: =MAX(0,CALC_ENGINE!AE29-ASSUMPTIONS!$C$33)
B35: AFFORDABILITY METRICS
B36: Total Employees | C36: =25
B37: Employees on Sacrifice | C37: =COUNTIF(CALC_ENGINE!K4:K28,"Yes")
B38: Participation Rate % | C38: =B37/B36
B39: ER NI Saving as % of Payroll | C39: =CALC_ENGINE!AF29/CALC_ENGINE!D29
B40: Avg Saving per Participating EE £ | C40: =CALC_ENGINE!AF29/MAX(1,COUNTIF(CALC_ENGINE!K4:K28,"Yes"))
B41: Total Pension as % of Payroll | C41: =(CALC_ENGINE!AB29+CALC_ENGINE!AD29)/CALC_ENGINE!D29

Sheet DEPT_SUMMARY
A1: DEPARTMENT-LEVEL SUMMARY — Salary Sacrifice Impact by Business Unit
B3: Department | C3: Headcount | D3: Total Salary £ | E3: Sacrificed £ | F3: EE Pension Post £ | G3: ER Pension Post £ | H3: Total Pension £ | I3: ER NI Saving £ | J3: EE Take-Home Chg £ | K3: ER Cost Change £
B4: Finance | C4: =COUNTIF(CALC_ENGINE!C4:CALC_ENGINE!C28,"Finance") | D4: =SUMIF(CALC_ENGINE!C4:CALC_ENGINE!C28,"Finance",CALC_ENGINE!D4:CALC_ENGINE!D28) | E4: =SUMIF(CALC_ENGINE!C4:CALC_ENGINE!C28,"Finance",CALC_ENGINE!V4:CALC_ENGINE!V28) | F4: =SUMIF(CALC_ENGINE!C4:CALC_ENGINE!C28,"Finance",CALC_ENGINE!AB4:CALC_ENGINE!AB28) | G4: =SUMIF(CALC_ENGINE!C4:CALC_ENGINE!C28,"Finance",CALC_ENGINE!AD4:CALC_ENGINE!AD28) | H4: =SUMIF(CALC_ENGINE!C4:CALC_ENGINE!C28,"Finance",CALC_ENGINE!AO4:CALC_ENGINE!AO28) | I4: =SUMIF(CALC_ENGINE!C4:CALC_ENGINE!C28,"Finance",CALC_ENGINE!AF4:CALC_ENGINE!AF28) | J4: =SUMIF(CALC_ENGINE!C4:CALC_ENGINE!C28,"Finance",CALC_ENGINE!AJ4:CALC_ENGINE!AJ28) | K4: =SUMIF(CALC_ENGINE!C4:CALC_ENGINE!C28,"Finance",CALC_ENGINE!AM4:CALC_ENGINE!AM28)
B5: HR | C5: =COUNTIF(CALC_ENGINE!C4:CALC_ENGINE!C28,"HR") | D5: =SUMIF(CALC_ENGINE!C4:CALC_ENGINE!C28,"HR",CALC_ENGINE!D4:CALC_ENGINE!D28) | E5: =SUMIF(CALC_ENGINE!C4:CALC_ENGINE!C28,"HR",CALC_ENGINE!V4:CALC_ENGINE!V28) | F5: =SUMIF(CALC_ENGINE!C4:CALC_ENGINE!C28,"HR",CALC_ENGINE!AB4:CALC_ENGINE!AB28) | G5: =SUMIF(CALC_ENGINE!C4:CALC_ENGINE!C28,"HR",CALC_ENGINE!AD4:CALC_ENGINE!AD28) | H5: =SUMIF(CALC_ENGINE!C4:CALC_ENGINE!C28,"HR",CALC_ENGINE!AO4:CALC_ENGINE!AO28) | I5: =SUMIF(CALC_ENGINE!C4:CALC_ENGINE!C28,"HR",CALC_ENGINE!AF4:CALC_ENGINE!AF28) | J5: =SUMIF(CALC_ENGINE!C4:CALC_ENGINE!C28,"HR",CALC_ENGINE!AJ4:CALC_ENGINE!AJ28) | K5: =SUMIF(CALC_ENGINE!C4:CALC_ENGINE!C28,"HR",CALC_ENGINE!AM4:CALC_ENGINE!AM28)
B6: Operations | C6: =COUNTIF(CALC_ENGINE!C4:CALC_ENGINE!C28,"Operations") | D6: =SUMIF(CALC_ENGINE!C4:CALC_ENGINE!C28,"Operations",CALC_ENGINE!D4:CALC_ENGINE!D28) | E6: =SUMIF(CALC_ENGINE!C4:CALC_ENGINE!C28,"Operations",CALC_ENGINE!V4:CALC_ENGINE!V28) | F6: =SUMIF(CALC_ENGINE!C4:CALC_ENGINE!C28,"Operations",CALC_ENGINE!AB4:CALC_ENGINE!AB28) | G6: =SUMIF(CALC_ENGINE!C4:CALC_ENGINE!C28,"Operations",CALC_ENGINE!AD4:CALC_ENGINE!AD28) | H6: =SUMIF(CALC_ENGINE!C4:CALC_ENGINE!C28,"Operations",CALC_ENGINE!AO4:CALC_ENGINE!AO28) | I6: =SUMIF(CALC_ENGINE!C4:CALC_ENGINE!C28,"Operations",CALC_ENGINE!AF4:CALC_ENGINE!AF28) | J6: =SUMIF(CALC_ENGINE!C4:CALC_ENGINE!C28,"Operations",CALC_ENGINE!AJ4:CALC_ENGINE!AJ28) | K6: =SUMIF(CALC_ENGINE!C4:CALC_ENGINE!C28,"Operations",CALC_ENGINE!AM4:CALC_ENGINE!AM28)
B7: Sales | C7: =COUNTIF(CALC_ENGINE!C4:CALC_ENGINE!C28,"Sales") | D7: =SUMIF(CALC_ENGINE!C4:CALC_ENGINE!C28,"Sales",CALC_ENGINE!D4:CALC_ENGINE!D28) | E7: =SUMIF(CALC_ENGINE!C4:CALC_ENGINE!C28,"Sales",CALC_ENGINE!V4:CALC_ENGINE!V28) | F7: =SUMIF(CALC_ENGINE!C4:CALC_ENGINE!C28,"Sales",CALC_ENGINE!AB4:CALC_ENGINE!AB28) | G7: =SUMIF(CALC_ENGINE!C4:CALC_ENGINE!C28,"Sales",CALC_ENGINE!AD4:CALC_ENGINE!AD28) | H7: =SUMIF(CALC_ENGINE!C4:CALC_ENGINE!C28,"Sales",CALC_ENGINE!AO4:CALC_ENGINE!AO28) | I7: =SUMIF(CALC_ENGINE!C4:CALC_ENGINE!C28,"Sales",CALC_ENGINE!AF4:CALC_ENGINE!AF28) | J7: =SUMIF(CALC_ENGINE!C4:CALC_ENGINE!C28,"Sales",CALC_ENGINE!AJ4:CALC_ENGINE!AJ28) | K7: =SUMIF(CALC_ENGINE!C4:CALC_ENGINE!C28,"Sales",CALC_ENGINE!AM4:CALC_ENGINE!AM28)
